<?xml version="1.0" ?>
<!-- Generated using onshape-to-robot -->
<!-- Onshape https://ricerobotics.onshape.com/documents/110d382abb90875ecabd9f16/w/1d5ff33beda38849f0d35cca/e/03c97318836ef18b6e2247c0 -->
<robot name="roverbody_urdf">
  <!-- Link front_plate -->
  <link name="front_plate">
    <inertial>
      <origin xyz="0.245405 0.21489 -0.0793223" rpy="0 0 0"/>
      <mass value="12.8268"/>
      <inertia ixx="0.640646" ixy="0.000135256" ixz="-0.00154043" iyy="1.05794" iyz="0.000943676" izz="1.28235"/>
    </inertial>
    <!-- Part top_plate -->
    <visual>
      <origin xyz="0.245231 0.215315 -0.239647" rpy="7.88861e-31 1.37096e-16 -2.22045e-16"/>
      <geometry>
        <mesh filename="package://assets/top_plate.stl"/>
      </geometry>
      <material name="top_plate_material">
        <color rgba="0.615686 0.811765 0.929412 1"/>
      </material>
    </visual>
    <collision>
      <origin xyz="0.245231 0.215315 -0.239647" rpy="7.88861e-31 1.37096e-16 -2.22045e-16"/>
      <geometry>
        <mesh filename="package://assets/top_plate.stl"/>
      </geometry>
    </collision>
    <!-- Part top_plate_2 -->
    <visual>
      <origin xyz="0.246036 0.214246 0.0761185" rpy="7.88861e-31 1.37096e-16 -1.11022e-16"/>
      <geometry>
        <mesh filename="package://assets/top_plate.stl"/>
      </geometry>
      <material name="top_plate_2_material">
        <color rgba="0.615686 0.811765 0.929412 1"/>
      </material>
    </visual>
    <collision>
      <origin xyz="0.246036 0.214246 0.0761185" rpy="7.88861e-31 1.37096e-16 -1.11022e-16"/>
      <geometry>
        <mesh filename="package://assets/top_plate.stl"/>
      </geometry>
    </collision>
    <!-- Part side_plate -->
    <visual>
      <origin xyz="0.245639 -0.0396343 -0.0792903" rpy="1.37096e-16 -7.88861e-31 1.5708"/>
      <geometry>
        <mesh filename="package://assets/side_plate.stl"/>
      </geometry>
      <material name="side_plate_material">
        <color rgba="0.615686 0.811765 0.929412 1"/>
      </material>
    </visual>
    <collision>
      <origin xyz="0.245639 -0.0396343 -0.0792903" rpy="1.37096e-16 -7.88861e-31 1.5708"/>
      <geometry>
        <mesh filename="package://assets/side_plate.stl"/>
      </geometry>
    </collision>
    <!-- Part front_plate -->
    <visual>
      <origin xyz="0.62316 0.21554 -0.0754249" rpy="6.02997e-09 -5.8438e-09 1.5708"/>
      <geometry>
        <mesh filename="package://assets/front_plate.stl"/>
      </geometry>
      <material name="front_plate_material">
        <color rgba="0.615686 0.811765 0.929412 1"/>
      </material>
    </visual>
    <collision>
      <origin xyz="0.62316 0.21554 -0.0754249" rpy="6.02997e-09 -5.8438e-09 1.5708"/>
      <geometry>
        <mesh filename="package://assets/front_plate.stl"/>
      </geometry>
    </collision>
    <!-- Part front_plate_2 -->
    <visual>
      <origin xyz="-0.136203 0.215031 -0.0777626" rpy="1.37096e-16 -7.88861e-31 1.5708"/>
      <geometry>
        <mesh filename="package://assets/front_plate.stl"/>
      </geometry>
      <material name="front_plate_2_material">
        <color rgba="0.615686 0.811765 0.929412 1"/>
      </material>
    </visual>
    <collision>
      <origin xyz="-0.136203 0.215031 -0.0777626" rpy="1.37096e-16 -7.88861e-31 1.5708"/>
      <geometry>
        <mesh filename="package://assets/front_plate.stl"/>
      </geometry>
    </collision>
    <!-- Part side_plate_2 -->
    <visual>
      <origin xyz="0.244856 0.466079 -0.0801256" rpy="1.37096e-16 -7.88861e-31 1.5708"/>
      <geometry>
        <mesh filename="package://assets/side_plate.stl"/>
      </geometry>
      <material name="side_plate_2_material">
        <color rgba="0.615686 0.811765 0.929412 1"/>
      </material>
    </visual>
    <collision>
      <origin xyz="0.244856 0.466079 -0.0801256" rpy="1.37096e-16 -7.88861e-31 1.5708"/>
      <geometry>
        <mesh filename="package://assets/side_plate.stl"/>
      </geometry>
    </collision>
  </link>
  <!-- Link bearing_block -->
  <link name="bearing_block">
    <inertial>
      <origin xyz="0.0421502 -0.0963282 -0.0164959" rpy="0 0 0"/>
      <mass value="1.28596"/>
      <inertia ixx="0.00835369" ixy="0.012101" ixz="0.000212206" iyy="0.0433755" iyz="-2.13059e-05" izz="0.0516386"/>
    </inertial>
    <!-- Part part_2 -->
    <visual>
      <origin xyz="0.0159546 -0.000589505 -0.00414236" rpy="1.5708 1.11022e-16 -3.13967"/>
      <geometry>
        <mesh filename="package://assets/part_2.stl"/>
      </geometry>
      <material name="part_2_material">
        <color rgba="0.917647 0.917647 0.917647 1"/>
      </material>
    </visual>
    <collision>
      <origin xyz="0.0159546 -0.000589505 -0.00414236" rpy="1.5708 1.11022e-16 -3.13967"/>
      <geometry>
        <mesh filename="package://assets/part_2.stl"/>
      </geometry>
    </collision>
    <!-- Part part_1 -->
    <visual>
      <origin xyz="-1.94289e-16 -4.16334e-17 -0.00705559" rpy="1.5708 1.11022e-16 -3.13967"/>
      <geometry>
        <mesh filename="package://assets/part_1.stl"/>
      </geometry>
      <material name="part_1_material">
        <color rgba="0.615686 0.811765 0.929412 1"/>
      </material>
    </visual>
    <collision>
      <origin xyz="-1.94289e-16 -4.16334e-17 -0.00705559" rpy="1.5708 1.11022e-16 -3.13967"/>
      <geometry>
        <mesh filename="package://assets/part_1.stl"/>
      </geometry>
    </collision>
    <!-- Part part_3 -->
    <visual>
      <origin xyz="-1.94289e-16 -4.16334e-17 -0.00705559" rpy="1.5708 1.11022e-16 -3.13967"/>
      <geometry>
        <mesh filename="package://assets/part_3.stl"/>
      </geometry>
      <material name="part_3_material">
        <color rgba="0.972549 0.529412 0.00392157 1"/>
      </material>
    </visual>
    <collision>
      <origin xyz="-1.94289e-16 -4.16334e-17 -0.00705559" rpy="1.5708 1.11022e-16 -3.13967"/>
      <geometry>
        <mesh filename="package://assets/part_3.stl"/>
      </geometry>
    </collision>
    <!-- Part part_9 -->
    <visual>
      <origin xyz="0.0159546 -0.000589505 -0.00414236" rpy="1.5708 1.11022e-16 -3.13967"/>
      <geometry>
        <mesh filename="package://assets/part_9.stl"/>
      </geometry>
      <material name="part_9_material">
        <color rgba="0.231373 0.380392 0.705882 1"/>
      </material>
    </visual>
    <collision>
      <origin xyz="0.0159546 -0.000589505 -0.00414236" rpy="1.5708 1.11022e-16 -3.13967"/>
      <geometry>
        <mesh filename="package://assets/part_9.stl"/>
      </geometry>
    </collision>
    <!-- Part part1 -->
    <visual>
      <origin xyz="0.101708 -0.0345516 -0.0164915" rpy="1.5708 -4.31458e-17 1.17166"/>
      <geometry>
        <mesh filename="package://assets/part1.stl"/>
      </geometry>
      <material name="part1_material">
        <color rgba="0.231373 0.380392 0.705882 1"/>
      </material>
    </visual>
    <collision>
      <origin xyz="0.101708 -0.0345516 -0.0164915" rpy="1.5708 -4.31458e-17 1.17166"/>
      <geometry>
        <mesh filename="package://assets/part1.stl"/>
      </geometry>
    </collision>
    <!-- Part part_1_2 -->
    <visual>
      <origin xyz="0.243969 -0.190134 -0.0270556" rpy="7.86554e-17 7.83536e-17 -2.35427"/>
      <geometry>
        <mesh filename="package://assets/part_1__2.stl"/>
      </geometry>
      <material name="part_1_2_material">
        <color rgba="0.615686 0.811765 0.929412 1"/>
      </material>
    </visual>
    <collision>
      <origin xyz="0.243969 -0.190134 -0.0270556" rpy="7.86554e-17 7.83536e-17 -2.35427"/>
      <geometry>
        <mesh filename="package://assets/part_1__2.stl"/>
      </geometry>
    </collision>
    <!-- Part part1_2 -->
    <visual>
      <origin xyz="-0.150024 -0.0353108 -0.0137249" rpy="1.5708 -4.22517e-17 -1.18038"/>
      <geometry>
        <mesh filename="package://assets/part1.stl"/>
      </geometry>
      <material name="part1_2_material">
        <color rgba="0.231373 0.380392 0.705882 1"/>
      </material>
    </visual>
    <collision>
      <origin xyz="-0.150024 -0.0353108 -0.0137249" rpy="1.5708 -4.22517e-17 -1.18038"/>
      <geometry>
        <mesh filename="package://assets/part1.stl"/>
      </geometry>
    </collision>
    <!-- Part bearing_block -->
    <visual>
      <origin xyz="0 -4.16334e-17 -0.00705559" rpy="1.5708 1.11022e-16 -3.13967"/>
      <geometry>
        <mesh filename="package://assets/bearing_block.stl"/>
      </geometry>
      <material name="bearing_block_material">
        <color rgba="0.647059 0.647059 0.647059 1"/>
      </material>
    </visual>
    <collision>
      <origin xyz="0 -4.16334e-17 -0.00705559" rpy="1.5708 1.11022e-16 -3.13967"/>
      <geometry>
        <mesh filename="package://assets/bearing_block.stl"/>
      </geometry>
    </collision>
  </link>
  <!-- Link part_1 -->
  <link name="part_1">
    <inertial>
      <origin xyz="3.02229e-16 6.54953e-17 -0.0317336" rpy="0 0 0"/>
      <mass value="1.44032"/>
      <inertia ixx="0.005616" ixy="-4.71572e-20" ixz="6.24317e-18" iyy="0.005616" iyz="-7.39264e-20" izz="0.00916748"/>
    </inertial>
    <!-- Part part_2_2 -->
    <visual>
      <origin xyz="-5.55112e-17 5.55112e-17 0" rpy="-3.14159 3.38294e-33 3.29182e-17"/>
      <geometry>
        <mesh filename="package://assets/part_2__2.stl"/>
      </geometry>
      <material name="part_2_2_material">
        <color rgba="0.647059 0.647059 0.647059 1"/>
      </material>
    </visual>
    <collision>
      <origin xyz="-5.55112e-17 5.55112e-17 0" rpy="-3.14159 3.38294e-33 3.29182e-17"/>
      <geometry>
        <mesh filename="package://assets/part_2__2.stl"/>
      </geometry>
    </collision>
    <!-- Part part_1_3 -->
    <visual>
      <origin xyz="-5.55112e-17 5.55112e-17 0" rpy="-3.14159 3.38294e-33 3.29182e-17"/>
      <geometry>
        <mesh filename="package://assets/part_1__3.stl"/>
      </geometry>
      <material name="part_1_3_material">
        <color rgba="0.615686 0.811765 0.929412 1"/>
      </material>
    </visual>
    <collision>
      <origin xyz="-5.55112e-17 5.55112e-17 0" rpy="-3.14159 3.38294e-33 3.29182e-17"/>
      <geometry>
        <mesh filename="package://assets/part_1__3.stl"/>
      </geometry>
    </collision>
  </link>
  <!-- Joint from bearing_block to part_1 -->
  <joint name="wheel_6" type="continuous">
    <origin xyz="0.299229 -0.245183 -0.0270556" rpy="8.10526e-17 7.58707e-17 -2.32318"/>
    <parent link="bearing_block"/>
    <child link="part_1"/>
    <axis xyz="0 0 1"/>
    <limit effort="10" velocity="10"/>
  </joint>
  <!-- Joint from front_plate to bearing_block -->
  <joint name="main_r" type="revolute">
    <origin xyz="0.245655 -0.0396343 -0.0792902" rpy="1.5708 -1.37096e-16 -3.14159"/>
    <parent link="front_plate"/>
    <child link="bearing_block"/>
    <axis xyz="0 0 1"/>
    <limit effort="10" velocity="10" lower="-3.141592653589793" upper="3.141592653589793"/>
  </joint>
  <!-- Link part_9 -->
  <link name="part_9">
    <inertial>
      <origin xyz="0.0368373 0.0984824 -0.0172168" rpy="0 0 0"/>
      <mass value="1.28596"/>
      <inertia ixx="0.00977329" ixy="-0.0139351" ixz="2.63549e-06" iyy="0.0419527" iyz="6.44644e-06" izz="0.0516386"/>
    </inertial>
    <!-- Part part_9_2 -->
    <visual>
      <origin xyz="0.0158987 0.00145821 -0.0269688" rpy="-1.5708 2.37928e-26 -3.08898"/>
      <geometry>
        <mesh filename="package://assets/part_9.stl"/>
      </geometry>
      <material name="part_9_2_material">
        <color rgba="0.231373 0.380392 0.705882 1"/>
      </material>
    </visual>
    <collision>
      <origin xyz="0.0158987 0.00145821 -0.0269688" rpy="-1.5708 2.37928e-26 -3.08898"/>
      <geometry>
        <mesh filename="package://assets/part_9.stl"/>
      </geometry>
    </collision>
    <!-- Part part_1_4 -->
    <visual>
      <origin xyz="8.32667e-17 -6.93889e-17 -0.0270556" rpy="-1.5708 2.37928e-26 -3.08898"/>
      <geometry>
        <mesh filename="package://assets/part_1.stl"/>
      </geometry>
      <material name="part_1_4_material">
        <color rgba="0.615686 0.811765 0.929412 1"/>
      </material>
    </visual>
    <collision>
      <origin xyz="8.32667e-17 -6.93889e-17 -0.0270556" rpy="-1.5708 2.37928e-26 -3.08898"/>
      <geometry>
        <mesh filename="package://assets/part_1.stl"/>
      </geometry>
    </collision>
    <!-- Part part1_3 -->
    <visual>
      <origin xyz="0.0996732 0.0400436 -0.0176197" rpy="-1.5708 -1.5132e-26 -1.11713"/>
      <geometry>
        <mesh filename="package://assets/part1.stl"/>
      </geometry>
      <material name="part1_3_material">
        <color rgba="0.231373 0.380392 0.705882 1"/>
      </material>
    </visual>
    <collision>
      <origin xyz="0.0996732 0.0400436 -0.0176197" rpy="-1.5708 -1.5132e-26 -1.11713"/>
      <geometry>
        <mesh filename="package://assets/part1.stl"/>
      </geometry>
    </collision>
    <!-- Part part_3_2 -->
    <visual>
      <origin xyz="-1.11022e-16 -1.52656e-16 -0.0270556" rpy="-1.5708 2.37928e-26 -3.08898"/>
      <geometry>
        <mesh filename="package://assets/part_3.stl"/>
      </geometry>
      <material name="part_3_2_material">
        <color rgba="0.972549 0.529412 0.00392157 1"/>
      </material>
    </visual>
    <collision>
      <origin xyz="-1.11022e-16 -1.52656e-16 -0.0270556" rpy="-1.5708 2.37928e-26 -3.08898"/>
      <geometry>
        <mesh filename="package://assets/part_3.stl"/>
      </geometry>
    </collision>
    <!-- Part part1_4 -->
    <visual>
      <origin xyz="-0.151726 0.0270815 -0.0203862" rpy="-1.5708 -3.13833e-27 1.23492"/>
      <geometry>
        <mesh filename="package://assets/part1.stl"/>
      </geometry>
      <material name="part1_4_material">
        <color rgba="0.231373 0.380392 0.705882 1"/>
      </material>
    </visual>
    <collision>
      <origin xyz="-0.151726 0.0270815 -0.0203862" rpy="-1.5708 -3.13833e-27 1.23492"/>
      <geometry>
        <mesh filename="package://assets/part1.stl"/>
      </geometry>
    </collision>
    <!-- Part bearing_block_2 -->
    <visual>
      <origin xyz="0 -1.38778e-17 -0.0270556" rpy="-1.5708 2.37928e-26 -3.08898"/>
      <geometry>
        <mesh filename="package://assets/bearing_block.stl"/>
      </geometry>
      <material name="bearing_block_2_material">
        <color rgba="0.647059 0.647059 0.647059 1"/>
      </material>
    </visual>
    <collision>
      <origin xyz="0 -1.38778e-17 -0.0270556" rpy="-1.5708 2.37928e-26 -3.08898"/>
      <geometry>
        <mesh filename="package://assets/bearing_block.stl"/>
      </geometry>
    </collision>
    <!-- Part part_2_3 -->
    <visual>
      <origin xyz="0.0158987 0.00145821 -0.0269688" rpy="-1.5708 2.37928e-26 -3.08898"/>
      <geometry>
        <mesh filename="package://assets/part_2.stl"/>
      </geometry>
      <material name="part_2_3_material">
        <color rgba="0.917647 0.917647 0.917647 1"/>
      </material>
    </visual>
    <collision>
      <origin xyz="0.0158987 0.00145821 -0.0269688" rpy="-1.5708 2.37928e-26 -3.08898"/>
      <geometry>
        <mesh filename="package://assets/part_2.stl"/>
      </geometry>
    </collision>
    <!-- Part part_1_5 -->
    <visual>
      <origin xyz="0.233243 0.203149 -0.0270556" rpy="1.23359e-26 -2.13121e-26 -0.73279"/>
      <geometry>
        <mesh filename="package://assets/part_1__2.stl"/>
      </geometry>
      <material name="part_1_5_material">
        <color rgba="0.615686 0.811765 0.929412 1"/>
      </material>
    </visual>
    <collision>
      <origin xyz="0.233243 0.203149 -0.0270556" rpy="1.23359e-26 -2.13121e-26 -0.73279"/>
      <geometry>
        <mesh filename="package://assets/part_1__2.stl"/>
      </geometry>
    </collision>
  </link>
  <!-- Link part1 -->
  <link name="part1">
    <inertial>
      <origin xyz="0.00335469 -0.0719336 -0.0083983" rpy="0 0 0"/>
      <mass value="1.26312"/>
      <inertia ixx="0.00358078" ixy="0.000419052" ixz="1.57251e-05" iyy="0.0209621" iyz="6.64463e-05" izz="0.0244531"/>
    </inertial>
    <!-- Part part_11 -->
    <visual>
      <origin xyz="-0.24435 0.113106 -0.04" rpy="-1.5708 -2.86425e-26 -0.0530108"/>
      <geometry>
        <mesh filename="package://assets/part_11.stl"/>
      </geometry>
      <material name="part_11_material">
        <color rgba="0.980392 0.713725 0.00392157 1"/>
      </material>
    </visual>
    <collision>
      <origin xyz="-0.24435 0.113106 -0.04" rpy="-1.5708 -2.86425e-26 -0.0530108"/>
      <geometry>
        <mesh filename="package://assets/part_11.stl"/>
      </geometry>
    </collision>
    <!-- Part part_6 -->
    <visual>
      <origin xyz="0.0552964 -0.202594 0.0229132" rpy="1.5708 1.51826e-25 1.51779"/>
      <geometry>
        <mesh filename="package://assets/part_6.stl"/>
      </geometry>
      <material name="part_6_material">
        <color rgba="0.972549 0.529412 0.00392157 1"/>
      </material>
    </visual>
    <collision>
      <origin xyz="0.0552964 -0.202594 0.0229132" rpy="1.5708 1.51826e-25 1.51779"/>
      <geometry>
        <mesh filename="package://assets/part_6.stl"/>
      </geometry>
    </collision>
    <!-- Part part_12 -->
    <visual>
      <origin xyz="-0.245798 0.113183 -0.04" rpy="-1.5708 -2.86425e-26 -0.0530108"/>
      <geometry>
        <mesh filename="package://assets/part_12.stl"/>
      </geometry>
      <material name="part_12_material">
        <color rgba="0.615686 0.811765 0.929412 1"/>
      </material>
    </visual>
    <collision>
      <origin xyz="-0.245798 0.113183 -0.04" rpy="-1.5708 -2.86425e-26 -0.0530108"/>
      <geometry>
        <mesh filename="package://assets/part_12.stl"/>
      </geometry>
    </collision>
    <!-- Part part_1_6 -->
    <visual>
      <origin xyz="0.123608 -0.0966681 -0.0170868" rpy="-1.11022e-16 -3.92523e-17 -2.40921"/>
      <geometry>
        <mesh filename="package://assets/part_1__2.stl"/>
      </geometry>
      <material name="part_1_6_material">
        <color rgba="0.615686 0.811765 0.929412 1"/>
      </material>
    </visual>
    <collision>
      <origin xyz="0.123608 -0.0966681 -0.0170868" rpy="-1.11022e-16 -3.92523e-17 -2.40921"/>
      <geometry>
        <mesh filename="package://assets/part_1__2.stl"/>
      </geometry>
    </collision>
    <!-- Part part1_5 -->
    <visual>
      <origin xyz="-0.0884719 -0.0322329 -0.00802691" rpy="-1.5708 1.52466e-25 1.86685"/>
      <geometry>
        <mesh filename="package://assets/part1.stl"/>
      </geometry>
      <material name="part1_5_material">
        <color rgba="0.231373 0.380392 0.705882 1"/>
      </material>
    </visual>
    <collision>
      <origin xyz="-0.0884719 -0.0322329 -0.00802691" rpy="-1.5708 1.52466e-25 1.86685"/>
      <geometry>
        <mesh filename="package://assets/part1.stl"/>
      </geometry>
    </collision>
    <!-- Part part_5 -->
    <visual>
      <origin xyz="-0.24435 0.113106 -0.04" rpy="-1.5708 -2.86425e-26 -0.0530108"/>
      <geometry>
        <mesh filename="package://assets/part_5.stl"/>
      </geometry>
      <material name="part_5_material">
        <color rgba="0.768627 0.886275 0.952941 1"/>
      </material>
    </visual>
    <collision>
      <origin xyz="-0.24435 0.113106 -0.04" rpy="-1.5708 -2.86425e-26 -0.0530108"/>
      <geometry>
        <mesh filename="package://assets/part_5.stl"/>
      </geometry>
    </collision>
    <!-- Part part1_6 -->
    <visual>
      <origin xyz="0.0854871 -0.0395907 -0.00786803" rpy="-1.5708 -1.32873e-25 -1.97287"/>
      <geometry>
        <mesh filename="package://assets/part1.stl"/>
      </geometry>
      <material name="part1_6_material">
        <color rgba="0.231373 0.380392 0.705882 1"/>
      </material>
    </visual>
    <collision>
      <origin xyz="0.0854871 -0.0395907 -0.00786803" rpy="-1.5708 -1.32873e-25 -1.97287"/>
      <geometry>
        <mesh filename="package://assets/part1.stl"/>
      </geometry>
    </collision>
    <!-- Part part_1_7 -->
    <visual>
      <origin xyz="-0.129242 -0.0832518 -0.0170868" rpy="8.71067e-26 1.27342e-25 2.30318"/>
      <geometry>
        <mesh filename="package://assets/part_1__4.stl"/>
      </geometry>
      <material name="part_1_7_material">
        <color rgba="0.615686 0.811765 0.929412 1"/>
      </material>
    </visual>
    <collision>
      <origin xyz="-0.129242 -0.0832518 -0.0170868" rpy="8.71067e-26 1.27342e-25 2.30318"/>
      <geometry>
        <mesh filename="package://assets/part_1__4.stl"/>
      </geometry>
    </collision>
    <!-- Part part_7 -->
    <visual>
      <origin xyz="-0.256347 0.114364 -0.0370868" rpy="-1.5708 -2.86425e-26 -0.0530108"/>
      <geometry>
        <mesh filename="package://assets/part_7.stl"/>
      </geometry>
      <material name="part_7_material">
        <color rgba="0.498039 0.498039 0.498039 1"/>
      </material>
    </visual>
    <collision>
      <origin xyz="-0.256347 0.114364 -0.0370868" rpy="-1.5708 -2.86425e-26 -0.0530108"/>
      <geometry>
        <mesh filename="package://assets/part_7.stl"/>
      </geometry>
    </collision>
  </link>
  <!-- Link part_4 -->
  <link name="part_4">
    <inertial>
      <origin xyz="0.0398116 -0.0814055 -0.28" rpy="0 0 0"/>
      <mass value="1.19385"/>
      <inertia ixx="0.0542354" ixy="0.00085494" ixz="-1.30104e-17" iyy="0.0522608" iyz="1.73472e-18" izz="0.00285881"/>
    </inertial>
    <!-- Part part_10 -->
    <visual>
      <origin xyz="-0.360292 -0.115867 0" rpy="1.5708 -4.2799e-26 0.0437451"/>
      <geometry>
        <mesh filename="package://assets/part_10.stl"/>
      </geometry>
      <material name="part_10_material">
        <color rgba="0.917647 0.917647 0.917647 1"/>
      </material>
    </visual>
    <collision>
      <origin xyz="-0.360292 -0.115867 0" rpy="1.5708 -4.2799e-26 0.0437451"/>
      <geometry>
        <mesh filename="package://assets/part_10.stl"/>
      </geometry>
    </collision>
    <!-- Part part_4 -->
    <visual>
      <origin xyz="-0.360292 -0.115867 1.11022e-16" rpy="1.5708 2.77556e-16 0.0437451"/>
      <geometry>
        <mesh filename="package://assets/part_4.stl"/>
      </geometry>
      <material name="part_4_material">
        <color rgba="0.498039 0.498039 0.498039 1"/>
      </material>
    </visual>
    <collision>
      <origin xyz="-0.360292 -0.115867 1.11022e-16" rpy="1.5708 2.77556e-16 0.0437451"/>
      <geometry>
        <mesh filename="package://assets/part_4.stl"/>
      </geometry>
    </collision>
    <!-- Part part_1_8 -->
    <visual>
      <origin xyz="0.0398504 -0.110363 -0.28" rpy="1.61454 -1.5708 0"/>
      <geometry>
        <mesh filename="package://assets/part_1__5.stl"/>
      </geometry>
      <material name="part_1_8_material">
        <color rgba="0.615686 0.811765 0.929412 1"/>
      </material>
    </visual>
    <collision>
      <origin xyz="0.0398504 -0.110363 -0.28" rpy="1.61454 -1.5708 0"/>
      <geometry>
        <mesh filename="package://assets/part_1__5.stl"/>
      </geometry>
    </collision>
    <!-- Part part_10_2 -->
    <visual>
      <origin xyz="-0.360292 -0.115867 -0.54" rpy="1.5708 -4.2799e-26 0.0437451"/>
      <geometry>
        <mesh filename="package://assets/part_10.stl"/>
      </geometry>
      <material name="part_10_2_material">
        <color rgba="0.917647 0.917647 0.917647 1"/>
      </material>
    </visual>
    <collision>
      <origin xyz="-0.360292 -0.115867 -0.54" rpy="1.5708 -4.2799e-26 0.0437451"/>
      <geometry>
        <mesh filename="package://assets/part_10.stl"/>
      </geometry>
    </collision>
    <!-- Part part_4_2 -->
    <visual>
      <origin xyz="-0.360292 -0.115867 -0.54" rpy="1.5708 2.77556e-16 0.0437451"/>
      <geometry>
        <mesh filename="package://assets/part_4.stl"/>
      </geometry>
      <material name="part_4_2_material">
        <color rgba="0.498039 0.498039 0.498039 1"/>
      </material>
    </visual>
    <collision>
      <origin xyz="-0.360292 -0.115867 -0.54" rpy="1.5708 2.77556e-16 0.0437451"/>
      <geometry>
        <mesh filename="package://assets/part_4.stl"/>
      </geometry>
    </collision>
  </link>
  <!-- Link part_5 -->
  <link name="part_5">
    <inertial>
      <origin xyz="-0.0944874 0.0867645 -0.0118626" rpy="0 0 0"/>
      <mass value="1.26312"/>
      <inertia ixx="0.00412348" ixy="0.00304981" ixz="3.96364e-06" iyy="0.0204209" iyz="9.18394e-05" izz="0.0244531"/>
    </inertial>
    <!-- Part part_11_2 -->
    <visual>
      <origin xyz="-0.374432 -0.0444928 0.02" rpy="1.5708 3.83049e-24 -0.150144"/>
      <geometry>
        <mesh filename="package://assets/part_11.stl"/>
      </geometry>
      <material name="part_11_2_material">
        <color rgba="0.980392 0.713725 0.00392157 1"/>
      </material>
    </visual>
    <collision>
      <origin xyz="-0.374432 -0.0444928 0.02" rpy="1.5708 3.83049e-24 -0.150144"/>
      <geometry>
        <mesh filename="package://assets/part_11.stl"/>
      </geometry>
    </collision>
    <!-- Part part_1_9 -->
    <visual>
      <origin xyz="-0.222074 0.124603 -0.0229132" rpy="-1.32519e-24 6.74232e-24 0.635254"/>
      <geometry>
        <mesh filename="package://assets/part_1__4.stl"/>
      </geometry>
      <material name="part_1_9_material">
        <color rgba="0.615686 0.811765 0.929412 1"/>
      </material>
    </visual>
    <collision>
      <origin xyz="-0.222074 0.124603 -0.0229132" rpy="-1.32519e-24 6.74232e-24 0.635254"/>
      <geometry>
        <mesh filename="package://assets/part_1__4.stl"/>
      </geometry>
    </collision>
    <!-- Part part_6_2 -->
    <visual>
      <origin xyz="-0.358751 -0.0474923 0.0170868" rpy="1.5708 3.83049e-24 -0.150144"/>
      <geometry>
        <mesh filename="package://assets/part_6.stl"/>
      </geometry>
      <material name="part_6_2_material">
        <color rgba="0.972549 0.529412 0.00392157 1"/>
      </material>
    </visual>
    <collision>
      <origin xyz="-0.358751 -0.0474923 0.0170868" rpy="1.5708 3.83049e-24 -0.150144"/>
      <geometry>
        <mesh filename="package://assets/part_6.stl"/>
      </geometry>
    </collision>
    <!-- Part part1_7 -->
    <visual>
      <origin xyz="-0.0205696 0.0385156 -0.012132" rpy="1.5708 4.05046e-24 1.76972"/>
      <geometry>
        <mesh filename="package://assets/part1.stl"/>
      </geometry>
      <material name="part1_7_material">
        <color rgba="0.231373 0.380392 0.705882 1"/>
      </material>
    </visual>
    <collision>
      <origin xyz="-0.0205696 0.0385156 -0.012132" rpy="1.5708 4.05046e-24 1.76972"/>
      <geometry>
        <mesh filename="package://assets/part1.stl"/>
      </geometry>
    </collision>
    <!-- Part part_5_2 -->
    <visual>
      <origin xyz="-0.374432 -0.0444928 0.02" rpy="1.5708 3.83049e-24 -0.150144"/>
      <geometry>
        <mesh filename="package://assets/part_5.stl"/>
      </geometry>
      <material name="part_5_2_material">
        <color rgba="0.768627 0.886275 0.952941 1"/>
      </material>
    </visual>
    <collision>
      <origin xyz="-0.374432 -0.0444928 0.02" rpy="1.5708 3.83049e-24 -0.150144"/>
      <geometry>
        <mesh filename="package://assets/part_5.stl"/>
      </geometry>
    </collision>
    <!-- Part part1_8 -->
    <visual>
      <origin xyz="-0.192436 0.0664072 -0.0119731" rpy="1.5708 -6.67067e-24 -2.07001"/>
      <geometry>
        <mesh filename="package://assets/part1.stl"/>
      </geometry>
      <material name="part1_8_material">
        <color rgba="0.231373 0.380392 0.705882 1"/>
      </material>
    </visual>
    <collision>
      <origin xyz="-0.192436 0.0664072 -0.0119731" rpy="1.5708 -6.67067e-24 -2.07001"/>
      <geometry>
        <mesh filename="package://assets/part1.stl"/>
      </geometry>
    </collision>
    <!-- Part part_12_2 -->
    <visual>
      <origin xyz="-0.375865 -0.0442759 0.02" rpy="1.5708 3.83049e-24 -0.150144"/>
      <geometry>
        <mesh filename="package://assets/part_12.stl"/>
      </geometry>
      <material name="part_12_2_material">
        <color rgba="0.615686 0.811765 0.929412 1"/>
      </material>
    </visual>
    <collision>
      <origin xyz="-0.375865 -0.0442759 0.02" rpy="1.5708 3.83049e-24 -0.150144"/>
      <geometry>
        <mesh filename="package://assets/part_12.stl"/>
      </geometry>
    </collision>
    <!-- Part part_7_2 -->
    <visual>
      <origin xyz="-0.386436 -0.043304 0.0170868" rpy="1.5708 3.83049e-24 -0.150144"/>
      <geometry>
        <mesh filename="package://assets/part_7.stl"/>
      </geometry>
      <material name="part_7_2_material">
        <color rgba="0.498039 0.498039 0.498039 1"/>
      </material>
    </visual>
    <collision>
      <origin xyz="-0.386436 -0.043304 0.0170868" rpy="1.5708 3.83049e-24 -0.150144"/>
      <geometry>
        <mesh filename="package://assets/part_7.stl"/>
      </geometry>
    </collision>
    <!-- Part part_1_10 -->
    <visual>
      <origin xyz="0.0282834 0.0867279 -0.0229132" rpy="-6.74232e-24 -1.32519e-24 -0.935542"/>
      <geometry>
        <mesh filename="package://assets/part_1__2.stl"/>
      </geometry>
      <material name="part_1_10_material">
        <color rgba="0.615686 0.811765 0.929412 1"/>
      </material>
    </visual>
    <collision>
      <origin xyz="0.0282834 0.0867279 -0.0229132" rpy="-6.74232e-24 -1.32519e-24 -0.935542"/>
      <geometry>
        <mesh filename="package://assets/part_1__2.stl"/>
      </geometry>
    </collision>
  </link>
  <!-- Link part_1_3 -->
  <link name="part_1_3">
    <inertial>
      <origin xyz="3.50801e-16 9.98414e-18 -0.0317336" rpy="0 0 0"/>
      <mass value="1.44032"/>
      <inertia ixx="0.005616" ixy="1.02787e-19" ixz="6.24317e-18" iyy="0.005616" iyz="-7.39264e-20" izz="0.00916748"/>
    </inertial>
    <!-- Part part_2_6 -->
    <visual>
      <origin xyz="-6.93889e-18 0 0" rpy="3.14159 -1.17755e-32 2.12398e-17"/>
      <geometry>
        <mesh filename="package://assets/part_2__2.stl"/>
      </geometry>
      <material name="part_2_6_material">
        <color rgba="0.647059 0.647059 0.647059 1"/>
      </material>
    </visual>
    <collision>
      <origin xyz="-6.93889e-18 0 0" rpy="3.14159 -1.17755e-32 2.12398e-17"/>
      <geometry>
        <mesh filename="package://assets/part_2__2.stl"/>
      </geometry>
    </collision>
    <!-- Part part_1_14 -->
    <visual>
      <origin xyz="-6.93889e-18 0 0" rpy="3.14159 -1.17755e-32 2.12398e-17"/>
      <geometry>
        <mesh filename="package://assets/part_1__3.stl"/>
      </geometry>
      <material name="part_1_14_material">
        <color rgba="0.615686 0.811765 0.929412 1"/>
      </material>
    </visual>
    <collision>
      <origin xyz="-6.93889e-18 0 0" rpy="3.14159 -1.17755e-32 2.12398e-17"/>
      <geometry>
        <mesh filename="package://assets/part_1__3.stl"/>
      </geometry>
    </collision>
  </link>
  <!-- Joint from part_5 to part_1_3 -->
  <joint name="wheel_5" type="continuous">
    <origin xyz="-0.268358 0.187387 -0.0229132" rpy="-9.99222e-17 -6.75354e-17 2.42953"/>
    <parent link="part_5"/>
    <child link="part_1_3"/>
    <axis xyz="0 0 1"/>
    <limit effort="10" velocity="10"/>
  </joint>
  <!-- Link part_1_4 -->
  <link name="part_1_4">
    <inertial>
      <origin xyz="3.85496e-16 9.98414e-18 -0.0317336" rpy="0 0 0"/>
      <mass value="1.44032"/>
      <inertia ixx="0.005616" ixy="1.97264e-19" ixz="6.24317e-18" iyy="0.005616" iyz="-7.39264e-20" izz="0.00916748"/>
    </inertial>
    <!-- Part part_1_15 -->
    <visual>
      <origin xyz="2.77556e-17 0 0" rpy="-3.14159 6.28023e-33 -2.00315e-17"/>
      <geometry>
        <mesh filename="package://assets/part_1__3.stl"/>
      </geometry>
      <material name="part_1_15_material">
        <color rgba="0.615686 0.811765 0.929412 1"/>
      </material>
    </visual>
    <collision>
      <origin xyz="2.77556e-17 0 0" rpy="-3.14159 6.28023e-33 -2.00315e-17"/>
      <geometry>
        <mesh filename="package://assets/part_1__3.stl"/>
      </geometry>
    </collision>
    <!-- Part part_2_7 -->
    <visual>
      <origin xyz="2.77556e-17 0 0" rpy="-3.14159 6.28023e-33 -2.00315e-17"/>
      <geometry>
        <mesh filename="package://assets/part_2__2.stl"/>
      </geometry>
      <material name="part_2_7_material">
        <color rgba="0.647059 0.647059 0.647059 1"/>
      </material>
    </visual>
    <collision>
      <origin xyz="2.77556e-17 0 0" rpy="-3.14159 6.28023e-33 -2.00315e-17"/>
      <geometry>
        <mesh filename="package://assets/part_2__2.stl"/>
      </geometry>
    </collision>
  </link>
  <!-- Joint from part_5 to part_1_4 -->
  <joint name="wheel_4" type="continuous">
    <origin xyz="0.0910672 0.133012 -0.0229132" rpy="2.95439e-17 2.43899e-18 -1.23566"/>
    <parent link="part_5"/>
    <child link="part_1_4"/>
    <axis xyz="0 0 1"/>
    <limit effort="10" velocity="10"/>
  </joint>
  <!-- Joint from part_4 to part_5 -->
  <joint name="sub2_r" type="revolute">
    <origin xyz="1.11022e-16 8.32667e-17 -0.56" rpy="6.78906e-26 -4.2799e-26 0.0437451"/>
    <parent link="part_4"/>
    <child link="part_5"/>
    <axis xyz="0 0 1"/>
    <limit effort="10" velocity="10" lower="-3.141592653589793" upper="3.141592653589793"/>
  </joint>
  <!-- Joint from part1 to part_4 -->
  <joint name="sub2_l" type="revolute">
    <origin xyz="0.113405 -0.0060173 -1.30048e-09" rpy="3.14159 -2.86425e-26 -0.0530108"/>
    <parent link="part1"/>
    <child link="part_4"/>
    <axis xyz="0 0 1"/>
    <limit effort="10" velocity="10" lower="-3.141592653589793" upper="3.141592653589793"/>
  </joint>
  <!-- Link part_1_5 -->
  <link name="part_1_5">
    <inertial>
      <origin xyz="1.91207e-16 -1.01038e-16 -0.0317336" rpy="0 0 0"/>
      <mass value="1.44032"/>
      <inertia ixx="0.005616" ixy="2.95083e-19" ixz="6.24317e-18" iyy="0.005616" iyz="-7.39264e-20" izz="0.00916748"/>
    </inertial>
    <!-- Part part_1_16 -->
    <visual>
      <origin xyz="-1.66533e-16 -1.11022e-16 0" rpy="-3.14159 1.41507e-32 -3.61543e-18"/>
      <geometry>
        <mesh filename="package://assets/part_1__3.stl"/>
      </geometry>
      <material name="part_1_16_material">
        <color rgba="0.615686 0.811765 0.929412 1"/>
      </material>
    </visual>
    <collision>
      <origin xyz="-1.66533e-16 -1.11022e-16 0" rpy="-3.14159 1.41507e-32 -3.61543e-18"/>
      <geometry>
        <mesh filename="package://assets/part_1__3.stl"/>
      </geometry>
    </collision>
    <!-- Part part_2_8 -->
    <visual>
      <origin xyz="-1.66533e-16 -1.11022e-16 0" rpy="-3.14159 1.41507e-32 -3.61543e-18"/>
      <geometry>
        <mesh filename="package://assets/part_2__2.stl"/>
      </geometry>
      <material name="part_2_8_material">
        <color rgba="0.647059 0.647059 0.647059 1"/>
      </material>
    </visual>
    <collision>
      <origin xyz="-1.66533e-16 -1.11022e-16 0" rpy="-3.14159 1.41507e-32 -3.61543e-18"/>
      <geometry>
        <mesh filename="package://assets/part_2__2.stl"/>
      </geometry>
    </collision>
  </link>
  <!-- Joint from part1 to part_1_5 -->
  <joint name="wheel_3" type="continuous">
    <origin xyz="0.175762 -0.154667 -0.0170868" rpy="2.61297e-16 -3.92524e-17 0.702372"/>
    <parent link="part1"/>
    <child link="part_1_5"/>
    <axis xyz="0 0 1"/>
    <limit effort="10" velocity="10"/>
  </joint>
  <!-- Link part_1_6 -->
  <link name="part_1_6">
    <inertial>
      <origin xyz="3.5774e-16 3.77397e-17 -0.0317336" rpy="0 0 0"/>
      <mass value="1.44032"/>
      <inertia ixx="0.005616" ixy="6.5347e-19" ixz="6.24317e-18" iyy="0.005616" iyz="-7.39264e-20" izz="0.00916748"/>
    </inertial>
    <!-- Part part_1_17 -->
    <visual>
      <origin xyz="0 2.77556e-17 0" rpy="3.14159 2.24566e-32 5.65561e-17"/>
      <geometry>
        <mesh filename="package://assets/part_1__3.stl"/>
      </geometry>
      <material name="part_1_17_material">
        <color rgba="0.615686 0.811765 0.929412 1"/>
      </material>
    </visual>
    <collision>
      <origin xyz="0 2.77556e-17 0" rpy="3.14159 2.24566e-32 5.65561e-17"/>
      <geometry>
        <mesh filename="package://assets/part_1__3.stl"/>
      </geometry>
    </collision>
    <!-- Part part_2_9 -->
    <visual>
      <origin xyz="0 2.77556e-17 0" rpy="3.14159 2.24566e-32 5.65561e-17"/>
      <geometry>
        <mesh filename="package://assets/part_2__2.stl"/>
      </geometry>
      <material name="part_2_9_material">
        <color rgba="0.647059 0.647059 0.647059 1"/>
      </material>
    </visual>
    <collision>
      <origin xyz="0 2.77556e-17 0" rpy="3.14159 2.24566e-32 5.65561e-17"/>
      <geometry>
        <mesh filename="package://assets/part_2__2.stl"/>
      </geometry>
    </collision>
  </link>
  <!-- Joint from part1 to part_1_6 -->
  <joint name="wheel_2" type="continuous">
    <origin xyz="-0.187242 -0.135406 -0.0170868" rpy="2.45551e-16 -1.76174e-16 -0.868424"/>
    <parent link="part1"/>
    <child link="part_1_6"/>
    <axis xyz="0 0 1"/>
    <limit effort="10" velocity="10"/>
  </joint>
  <!-- Joint from part_9 to part1 -->
  <joint name="sub_l" type="revolute">
    <origin xyz="-0.239014 0.0881738 -0.0269688" rpy="6.34714e-27 2.37928e-26 -3.08898"/>
    <parent link="part_9"/>
    <child link="part1"/>
    <axis xyz="0 0 1"/>
    <limit effort="10" velocity="10" lower="-3.141592653589793" upper="3.141592653589793"/>
  </joint>
  <!-- Link part_1_7 -->
  <link name="part_1_7">
    <inertial>
      <origin xyz="3.29985e-16 9.98414e-18 -0.0317336" rpy="0 0 0"/>
      <mass value="1.44032"/>
      <inertia ixx="0.005616" ixy="-4.92698e-19" ixz="6.24317e-18" iyy="0.005616" iyz="-7.39264e-20" izz="0.00916748"/>
    </inertial>
    <!-- Part part_1_18 -->
    <visual>
      <origin xyz="-2.77556e-17 0 0" rpy="3.14159 3.65913e-34 -6.52594e-17"/>
      <geometry>
        <mesh filename="package://assets/part_1__3.stl"/>
      </geometry>
      <material name="part_1_18_material">
        <color rgba="0.615686 0.811765 0.929412 1"/>
      </material>
    </visual>
    <collision>
      <origin xyz="-2.77556e-17 0 0" rpy="3.14159 3.65913e-34 -6.52594e-17"/>
      <geometry>
        <mesh filename="package://assets/part_1__3.stl"/>
      </geometry>
    </collision>
    <!-- Part part_2_10 -->
    <visual>
      <origin xyz="-2.77556e-17 0 0" rpy="3.14159 3.65913e-34 -6.52594e-17"/>
      <geometry>
        <mesh filename="package://assets/part_2__2.stl"/>
      </geometry>
      <material name="part_2_10_material">
        <color rgba="0.647059 0.647059 0.647059 1"/>
      </material>
    </visual>
    <collision>
      <origin xyz="-2.77556e-17 0 0" rpy="3.14159 3.65913e-34 -6.52594e-17"/>
      <geometry>
        <mesh filename="package://assets/part_2__2.stl"/>
      </geometry>
    </collision>
  </link>
  <!-- Joint from part_9 to part_1_7 -->
  <joint name="wheel_1" type="continuous">
    <origin xyz="0.285421 0.261127 -0.0270556" rpy="-1.14868e-17 1.33339e-16 2.44389"/>
    <parent link="part_9"/>
    <child link="part_1_7"/>
    <axis xyz="0 0 1"/>
    <limit effort="10" velocity="10"/>
  </joint>
  <!-- Joint from front_plate to part_9 -->
  <joint name="main_l" type="revolute">
    <origin xyz="0.239856 0.469254 -0.0801256" rpy="-1.5708 -1.37096e-16 3.14159"/>
    <parent link="front_plate"/>
    <child link="part_9"/>
    <axis xyz="0 0 1"/>
    <limit effort="10" velocity="10" lower="-3.141592653589793" upper="3.141592653589793"/>
  </joint>
</robot>
