<?xml version="1.0" ?>
<!-- Generated using onshape-to-robot -->
<!-- Onshape https://ricerobotics.onshape.com/documents/73f85d42ea83309537336bf0/w/78d26b2e101d193e4048c5b2/e/930bb66fd56aefb4c0af6f33 -->
<robot name="urdf">
  <!-- Link part_1__length_0_5_meter -->
  <link name="part_1__length_0_5_meter">
    <inertial>
      <origin xyz="0 0 0" rpy="0 0 0"/>
      <mass value="1e-09"/>
      <inertia ixx="1e-09" ixy="0" ixz="0" iyy="1e-09" iyz="0" izz="1e-09"/>
    </inertial>
    <!-- Part part_1__length_0_5_meter -->
    <visual>
      <origin xyz="0.01 -0.25 0.01" rpy="1.5708 -0 3.14159"/>
      <geometry>
        <mesh filename="package://urdf_viewer/urdf/assets/part_1__length_0_5_meter.stl"/>
      </geometry>
      <material name="part_1__length_0_5_meter_material">
        <color rgba="0.615686 0.811765 0.929412 1"/>
      </material>
    </visual>
    <collision>
      <origin xyz="0.01 -0.25 0.01" rpy="1.5708 -0 3.14159"/>
      <geometry>
        <mesh filename="package://urdf_viewer/urdf/assets/part_1__length_0_5_meter.stl"/>
      </geometry>
    </collision>
    <!-- Part part_6 -->
    <visual>
      <origin xyz="0.02175 0.275 0.04586" rpy="-1.5708 -0 3.14159"/>
      <geometry>
        <mesh filename="package://urdf_viewer/urdf/assets/part_6.stl"/>
      </geometry>
      <material name="part_6_material">
        <color rgba="0.768627 0.886275 0.952941 1"/>
      </material>
    </visual>
    <collision>
      <origin xyz="0.02175 0.275 0.04586" rpy="-1.5708 -0 3.14159"/>
      <geometry>
        <mesh filename="package://urdf_viewer/urdf/assets/part_6.stl"/>
      </geometry>
    </collision>
    <!-- Part part_7 -->
    <visual>
      <origin xyz="0.02175 0.270316 0.04586" rpy="-1.5708 -0 -3.14159"/>
      <geometry>
        <mesh filename="package://urdf_viewer/urdf/assets/part_7.stl"/>
      </geometry>
      <material name="part_7_material">
        <color rgba="0.972549 0.529412 0.00392157 1"/>
      </material>
    </visual>
    <collision>
      <origin xyz="0.02175 0.270316 0.04586" rpy="-1.5708 -0 -3.14159"/>
      <geometry>
        <mesh filename="package://urdf_viewer/urdf/assets/part_7.stl"/>
      </geometry>
    </collision>
  </link>
  <!-- Link 6inch_shorter_arm_body -->
  <link name="6inch_shorter_arm_body">
    <inertial>
      <origin xyz="-0.015875 0.0761547 0.0328074" rpy="0 0 0"/>
      <mass value="0.278123"/>
      <inertia ixx="0.000850662" ixy="-1.05083e-22" ixz="-4.64604e-20" iyy="0.000375756" iyz="-5.93342e-07" izz="0.000556871"/>
    </inertial>
    <!-- Part 6inch_shorter_arm_body_special -->
    <visual>
      <origin xyz="-0.03175 0.1524 -0.015875" rpy="1.5708 2.18548e-16 2.63027e-32"/>
      <geometry>
        <mesh filename="package://urdf_viewer/urdf/assets/6inch_shorter_arm_body_special.stl"/>
      </geometry>
      <material name="6inch_shorter_arm_body_special_material">
        <color rgba="0.615686 0.811765 0.929412 1"/>
      </material>
    </visual>
    <collision>
      <origin xyz="-0.03175 0.1524 -0.015875" rpy="1.5708 2.18548e-16 2.63027e-32"/>
      <geometry>
        <mesh filename="package://urdf_viewer/urdf/assets/6inch_shorter_arm_body_special.stl"/>
      </geometry>
    </collision>
    <!-- Part 6inch_shorter_arm_body -->
    <visual>
      <origin xyz="-0.03175 0.1524 0.049625" rpy="1.5708 2.18548e-16 2.63027e-32"/>
      <geometry>
        <mesh filename="package://urdf_viewer/urdf/assets/6inch_shorter_arm_body.stl"/>
      </geometry>
      <material name="6inch_shorter_arm_body_material">
        <color rgba="0.615686 0.811765 0.929412 1"/>
      </material>
    </visual>
    <collision>
      <origin xyz="-0.03175 0.1524 0.049625" rpy="1.5708 2.18548e-16 2.63027e-32"/>
      <geometry>
        <mesh filename="package://urdf_viewer/urdf/assets/6inch_shorter_arm_body.stl"/>
      </geometry>
    </collision>
  </link>
  <!-- Link 20inch_longer_arm_body -->
  <link name="20inch_longer_arm_body">
    <inertial>
      <origin xyz="0 -0.23495 -0.015875" rpy="0 0 0"/>
      <mass value="0.490242"/>
      <inertia ixx="0.0102535" ixy="2.80019e-19" ixz="9.05113e-22" iyy="0.000135645" iyz="-4.94891e-34" izz="0.0102555"/>
    </inertial>
    <!-- Part 20inch_longer_arm_body -->
    <visual>
      <origin xyz="0.041275 0.01905 -0.03175" rpy="1.5708 4.37096e-16 2.70029e-17"/>
      <geometry>
        <mesh filename="package://urdf_viewer/urdf/assets/20inch_longer_arm_body.stl"/>
      </geometry>
      <material name="20inch_longer_arm_body_material">
        <color rgba="0.647059 0.647059 0.647059 1"/>
      </material>
    </visual>
    <collision>
      <origin xyz="0.041275 0.01905 -0.03175" rpy="1.5708 4.37096e-16 2.70029e-17"/>
      <geometry>
        <mesh filename="package://urdf_viewer/urdf/assets/20inch_longer_arm_body.stl"/>
      </geometry>
    </collision>
  </link>
  <!-- Link 6inch_shorter_arm_body_2 -->
  <link name="6inch_shorter_arm_body_2">
    <inertial>
      <origin xyz="-0.048899 -0.0295805 -0.016875" rpy="0 0 0"/>
      <mass value="0.139231"/>
      <inertia ixx="0.000102604" ixy="-0.00010526" ixz="3.25314e-19" iyy="0.000212932" iyz="-5.02194e-19" izz="0.000278678"/>
    </inertial>
    <!-- Part 6inch_shorter_arm_body_2 -->
    <visual>
      <origin xyz="-0.122315 -0.0554382 -0.001" rpy="-1.5708 -2.16216e-15 -1.02676"/>
      <geometry>
        <mesh filename="package://urdf_viewer/urdf/assets/6inch_shorter_arm_body.stl"/>
      </geometry>
      <material name="6inch_shorter_arm_body_2_material">
        <color rgba="0.615686 0.811765 0.929412 1"/>
      </material>
    </visual>
    <collision>
      <origin xyz="-0.122315 -0.0554382 -0.001" rpy="-1.5708 -2.16216e-15 -1.02676"/>
      <geometry>
        <mesh filename="package://urdf_viewer/urdf/assets/6inch_shorter_arm_body.stl"/>
      </geometry>
    </collision>
  </link>
  <!-- Frame closing_shoulder_loop_1 (dummy link + fixed joint) -->
  <link name="closing_shoulder_loop_1">
    <origin xyz="0 0 0" rpy="0 -0 0"/>
    <inertial>
      <origin xyz="0 0 0" rpy="0 0 0"/>
      <mass value="1e-9"/>
      <inertia ixx="0" ixy="0" ixz="0" iyy="0" iyz="0" izz="0"/>
    </inertial>
  </link>
  <joint name="closing_shoulder_loop_1_frame" type="fixed">
    <origin xyz="-0.0977981 -0.059161 -0.001" rpy="4.73045e-16 -2.16216e-15 -1.02676"/>
    <parent link="6inch_shorter_arm_body_2"/>
    <child link="closing_shoulder_loop_1"/>
    <axis xyz="0 0 0"/>
  </joint>
  <!-- Frame closing_shoulder_loop_1_z (dummy link + fixed joint) -->
  <link name="closing_shoulder_loop_1_z">
    <origin xyz="0 0 0" rpy="0 -0 0"/>
    <inertial>
      <origin xyz="0 0 0" rpy="0 0 0"/>
      <mass value="1e-9"/>
      <inertia ixx="0" ixy="0" ixz="0" iyy="0" iyz="0" izz="0"/>
    </inertial>
  </link>
  <joint name="closing_shoulder_loop_1_z_frame" type="fixed">
    <origin xyz="-0.0977981 -0.059161 0.099" rpy="4.73045e-16 -2.16216e-15 -1.02676"/>
    <parent link="6inch_shorter_arm_body_2"/>
    <child link="closing_shoulder_loop_1_z"/>
    <axis xyz="0 0 0"/>
  </joint>
  <!-- Link 20inch_longer_arm_body_2 -->
  <link name="20inch_longer_arm_body_2">
    <inertial>
      <origin xyz="0.152784 0.17849 -0.016875" rpy="0 0 0"/>
      <mass value="0.490242"/>
      <inertia ixx="0.00597496" ixy="-0.00499835" ixz="-3.12812e-18" iyy="0.00441414" iyz="2.39047e-18" izz="0.0102555"/>
    </inertial>
    <!-- Part 20inch_longer_arm_body_2 -->
    <visual>
      <origin xyz="0.2866 0.398292 -0.001" rpy="-1.5708 -3.83372e-16 2.43364"/>
      <geometry>
        <mesh filename="package://urdf_viewer/urdf/assets/20inch_longer_arm_body.stl"/>
      </geometry>
      <material name="20inch_longer_arm_body_2_material">
        <color rgba="0.647059 0.647059 0.647059 1"/>
      </material>
    </visual>
    <collision>
      <origin xyz="0.2866 0.398292 -0.001" rpy="-1.5708 -3.83372e-16 2.43364"/>
      <geometry>
        <mesh filename="package://urdf_viewer/urdf/assets/20inch_longer_arm_body.stl"/>
      </geometry>
    </collision>
  </link>
  <!-- Frame closing_elbow_loop_1 (dummy link + fixed joint) -->
  <link name="closing_elbow_loop_1">
    <origin xyz="0 0 0" rpy="0 -0 0"/>
    <inertial>
      <origin xyz="0 0 0" rpy="0 0 0"/>
      <mass value="1e-9"/>
      <inertia ixx="0" ixy="0" ixz="0" iyy="0" iyz="0" izz="0"/>
    </inertial>
  </link>
  <joint name="closing_elbow_loop_1_frame" type="fixed">
    <origin xyz="0.305568 0.356979 -0.001" rpy="1.60818e-15 -3.83372e-16 2.43364"/>
    <parent link="20inch_longer_arm_body_2"/>
    <child link="closing_elbow_loop_1"/>
    <axis xyz="0 0 0"/>
  </joint>
  <!-- Frame closing_elbow_loop_1_z (dummy link + fixed joint) -->
  <link name="closing_elbow_loop_1_z">
    <origin xyz="0 0 0" rpy="0 -0 0"/>
    <inertial>
      <origin xyz="0 0 0" rpy="0 0 0"/>
      <mass value="1e-9"/>
      <inertia ixx="0" ixy="0" ixz="0" iyy="0" iyz="0" izz="0"/>
    </inertial>
  </link>
  <joint name="closing_elbow_loop_1_z_frame" type="fixed">
    <origin xyz="0.305568 0.356979 0.099" rpy="1.60818e-15 -3.83372e-16 2.43364"/>
    <parent link="20inch_longer_arm_body_2"/>
    <child link="closing_elbow_loop_1_z"/>
    <axis xyz="0 0 0"/>
  </joint>
  <!-- Joint from 6inch_shorter_arm_body_2 to 20inch_longer_arm_body_2 -->
  <joint name="elbow_2" type="revolute">
    <origin xyz="-0.0977981 -0.059161 -0.03275" rpy="4.73045e-16 -2.16216e-15 -1.02676"/>
    <parent link="6inch_shorter_arm_body_2"/>
    <child link="20inch_longer_arm_body_2"/>
    <axis xyz="0 0 1"/>
    <limit effort="10" velocity="10" lower="-3.141592653589793" upper="3.141592653589793"/>
    <mimic joint="elbow_1" multiplier="1.0"/>
  </joint>
  <!-- Link 20inch_longer_arm_body_3 -->
  <link name="20inch_longer_arm_body_3">
    <inertial>
      <origin xyz="0.152784 0.17849 -0.016875" rpy="0 0 0"/>
      <mass value="0.490242"/>
      <inertia ixx="0.00597496" ixy="-0.00499835" ixz="-1.08566e-17" iyy="0.00441414" iyz="9.01551e-18" izz="0.0102555"/>
    </inertial>
    <!-- Part 20inch_longer_arm_body_3 -->
    <visual>
      <origin xyz="0.2866 0.398292 -0.001" rpy="-1.5708 -1.37615e-15 2.43364"/>
      <geometry>
        <mesh filename="package://urdf_viewer/urdf/assets/20inch_longer_arm_body.stl"/>
      </geometry>
      <material name="20inch_longer_arm_body_3_material">
        <color rgba="0.647059 0.647059 0.647059 1"/>
      </material>
    </visual>
    <collision>
      <origin xyz="0.2866 0.398292 -0.001" rpy="-1.5708 -1.37615e-15 2.43364"/>
      <geometry>
        <mesh filename="package://urdf_viewer/urdf/assets/20inch_longer_arm_body.stl"/>
      </geometry>
    </collision>
  </link>
  <!-- Link 6inch_shorter_arm_body_3 -->
  <link name="6inch_shorter_arm_body_3">
    <inertial>
      <origin xyz="-0.0371637 -0.0434164 -0.016875" rpy="0 0 0"/>
      <mass value="0.139231"/>
      <inertia ixx="0.000176101" ixy="-0.000117417" ixz="-2.91548e-20" iyy="0.000139435" iyz="2.61525e-20" izz="0.000278678"/>
    </inertial>
    <!-- Part 6inch_shorter_arm_body_3 -->
    <visual>
      <origin xyz="-0.0746551 -0.111628 -0.03275" rpy="1.5708 -1.41555e-16 2.43364"/>
      <geometry>
        <mesh filename="package://urdf_viewer/urdf/assets/6inch_shorter_arm_body.stl"/>
      </geometry>
      <material name="6inch_shorter_arm_body_3_material">
        <color rgba="0.615686 0.811765 0.929412 1"/>
      </material>
    </visual>
    <collision>
      <origin xyz="-0.0746551 -0.111628 -0.03275" rpy="1.5708 -1.41555e-16 2.43364"/>
      <geometry>
        <mesh filename="package://urdf_viewer/urdf/assets/6inch_shorter_arm_body.stl"/>
      </geometry>
    </collision>
  </link>
  <!-- Frame closing_elbow_loop_2 (dummy link + fixed joint) -->
  <link name="closing_elbow_loop_2">
    <origin xyz="0 0 0" rpy="0 -0 0"/>
    <inertial>
      <origin xyz="0 0 0" rpy="0 0 0"/>
      <mass value="1e-9"/>
      <inertia ixx="0" ixy="0" ixz="0" iyy="0" iyz="0" izz="0"/>
    </inertial>
  </link>
  <joint name="closing_elbow_loop_2_frame" type="fixed">
    <origin xyz="-0.0743273 -0.0868328 5.55112e-17" rpy="3.14159 2.33498e-17 -2.27875"/>
    <parent link="6inch_shorter_arm_body_3"/>
    <child link="closing_elbow_loop_2"/>
    <axis xyz="0 0 0"/>
  </joint>
  <!-- Frame closing_elbow_loop_2_z (dummy link + fixed joint) -->
  <link name="closing_elbow_loop_2_z">
    <origin xyz="0 0 0" rpy="0 -0 0"/>
    <inertial>
      <origin xyz="0 0 0" rpy="0 0 0"/>
      <mass value="1e-9"/>
      <inertia ixx="0" ixy="0" ixz="0" iyy="0" iyz="0" izz="0"/>
    </inertial>
  </link>
  <joint name="closing_elbow_loop_2_z_frame" type="fixed">
    <origin xyz="-0.0743273 -0.0868328 -0.1" rpy="3.14159 2.33498e-17 -2.27875"/>
    <parent link="6inch_shorter_arm_body_3"/>
    <child link="closing_elbow_loop_2_z"/>
    <axis xyz="0 0 0"/>
  </joint>
  <!-- Joint from 20inch_longer_arm_body_3 to 6inch_shorter_arm_body_3 -->
  <joint name="elbow_end_1" type="revolute">
    <origin xyz="0.305568 0.356979 -0.001" rpy="-3.14159 -1.37615e-15 2.43364"/>
    <parent link="20inch_longer_arm_body_3"/>
    <child link="6inch_shorter_arm_body_3"/>
    <axis xyz="0 0 1"/>
    <limit effort="10" velocity="10" lower="-3.141592653589793" upper="3.141592653589793"/>
    <mimic joint="elbow_1" multiplier="1.0"/>
  </joint>
  <!-- Joint from 6inch_shorter_arm_body_2 to 20inch_longer_arm_body_3 -->
  <joint name="elbow_1" type="revolute">
    <origin xyz="3.22225e-16 3.33067e-16 -0.03275" rpy="4.73045e-16 -2.16216e-15 -1.02676"/>
    <parent link="6inch_shorter_arm_body_2"/>
    <child link="20inch_longer_arm_body_3"/>
    <axis xyz="0 0 1"/>
    <limit effort="10" velocity="10" lower="-3.141592653589793" upper="3.141592653589793"/>
  </joint>
  <!-- Joint from 20inch_longer_arm_body to 6inch_shorter_arm_body_2 -->
  <joint name="shoulder_end_1" type="revolute">
    <origin xyz="-8.32667e-17 -0.4699 0" rpy="-3.14159 -2.90661e-32 2.70029e-17"/>
    <parent link="20inch_longer_arm_body"/>
    <child link="6inch_shorter_arm_body_2"/>
    <axis xyz="0 0 1"/>
    <limit effort="10" velocity="10" lower="-3.141592653589793" upper="3.141592653589793"/>
    <mimic joint="shoulder_1" multiplier="1.0"/>
  </joint>
  <!-- Joint from 6inch_shorter_arm_body to 20inch_longer_arm_body -->
  <joint name="shoulder_1" type="revolute">
    <origin xyz="-0.015875 0.01905 0.048625" rpy="1.90309e-16 2.77821e-16 -1.02676"/>
    <parent link="6inch_shorter_arm_body"/>
    <child link="20inch_longer_arm_body"/>
    <axis xyz="0 0 1"/>
    <limit effort="10" velocity="10" lower="-3.141592653589793" upper="3.141592653589793"/>
  </joint>
  <!-- Link 20inch_longer_arm_body_4 -->
  <link name="20inch_longer_arm_body_4">
    <inertial>
      <origin xyz="9.02056e-17 0.23495 -0.015875" rpy="0 0 0"/>
      <mass value="0.490242"/>
      <inertia ixx="0.0102535" ixy="-4.50224e-19" ixz="9.05113e-22" iyy="0.000135645" iyz="5.90785e-35" izz="0.0102555"/>
    </inertial>
    <!-- Part 20inch_longer_arm_body_4 -->
    <visual>
      <origin xyz="0.041275 0.48895 -0.03175" rpy="1.5708 4.37096e-16 -4.4585e-17"/>
      <geometry>
        <mesh filename="package://urdf_viewer/urdf/assets/20inch_longer_arm_body.stl"/>
      </geometry>
      <material name="20inch_longer_arm_body_4_material">
        <color rgba="0.647059 0.647059 0.647059 1"/>
      </material>
    </visual>
    <collision>
      <origin xyz="0.041275 0.48895 -0.03175" rpy="1.5708 4.37096e-16 -4.4585e-17"/>
      <geometry>
        <mesh filename="package://urdf_viewer/urdf/assets/20inch_longer_arm_body.stl"/>
      </geometry>
    </collision>
  </link>
  <!-- Frame closing_shoulder_loop_2 (dummy link + fixed joint) -->
  <link name="closing_shoulder_loop_2">
    <origin xyz="0 0 0" rpy="0 -0 0"/>
    <inertial>
      <origin xyz="0 0 0" rpy="0 0 0"/>
      <mass value="1e-9"/>
      <inertia ixx="0" ixy="0" ixz="0" iyy="0" iyz="0" izz="0"/>
    </inertial>
  </link>
  <joint name="closing_shoulder_loop_2_frame" type="fixed">
    <origin xyz="1.38778e-16 0.4699 -0.03275" rpy="-4.37096e-16 -4.05289e-32 -1.5708"/>
    <parent link="20inch_longer_arm_body_4"/>
    <child link="closing_shoulder_loop_2"/>
    <axis xyz="0 0 0"/>
  </joint>
  <!-- Frame closing_shoulder_loop_2_z (dummy link + fixed joint) -->
  <link name="closing_shoulder_loop_2_z">
    <origin xyz="0 0 0" rpy="0 -0 0"/>
    <inertial>
      <origin xyz="0 0 0" rpy="0 0 0"/>
      <mass value="1e-9"/>
      <inertia ixx="0" ixy="0" ixz="0" iyy="0" iyz="0" izz="0"/>
    </inertial>
  </link>
  <joint name="closing_shoulder_loop_2_z_frame" type="fixed">
    <origin xyz="1.94289e-16 0.4699 0.06725" rpy="-4.37096e-16 -4.05289e-32 -1.5708"/>
    <parent link="20inch_longer_arm_body_4"/>
    <child link="closing_shoulder_loop_2_z"/>
    <axis xyz="0 0 0"/>
  </joint>
  <!-- Joint from 6inch_shorter_arm_body to 20inch_longer_arm_body_4 -->
  <joint name="shoulder_2" type="revolute">
    <origin xyz="-0.015875 0.13335 0.016875" rpy="-3.14159 7.57238e-16 -1.02676"/>
    <parent link="6inch_shorter_arm_body"/>
    <child link="20inch_longer_arm_body_4"/>
    <axis xyz="0 0 1"/>
    <limit effort="10" velocity="10" lower="-3.141592653589793" upper="3.141592653589793"/>
    <mimic joint="shoulder_1" multiplier="-1.0"/>
  </joint>
  <!-- Joint from part_1__length_0_5_meter to 6inch_shorter_arm_body -->
  <joint name="slider" type="prismatic">
    <origin xyz="0.0762 0.075 0.08599" rpy="-1.5708 1.5708 0"/>
    <parent link="part_1__length_0_5_meter"/>
    <child link="6inch_shorter_arm_body"/>
    <axis xyz="0 0 1"/>
    <limit effort="10" velocity="10" lower="-0.25" upper="1.66533e-16"/>
  </joint>
</robot>
