<?xml version="1.0" ?>
<!-- Generated using onshape-to-robot -->
<!-- Onshape https://ricerobotics.onshape.com/documents/110d382abb90875ecabd9f16/w/1d5ff33beda38849f0d35cca/e/03c97318836ef18b6e2247c0 -->
<robot name="roverbody_urdf">
  <!-- Link front_plate -->
  <link name="front_plate">
    <inertial>
      <origin xyz="0 0 0" rpy="0 0 0"/>
      <mass value="1e-09"/>
      <inertia ixx="1e-09" ixy="0" ixz="0" iyy="1e-09" iyz="0" izz="1e-09"/>
    </inertial>
    <!-- Part top_plate -->
    <visual>
      <origin xyz="0.245231 0.215315 -0.239647" rpy="7.88861e-31 1.37096e-16 -2.22045e-16"/>
      <geometry>
        <mesh filename="package://assets/top_plate.stl"/>
      </geometry>
      <material name="top_plate_material">
        <color rgba="0.615686 0.811765 0.929412 1"/>
      </material>
    </visual>
    <collision>
      <origin xyz="0.245231 0.215315 -0.239647" rpy="7.88861e-31 1.37096e-16 -2.22045e-16"/>
      <geometry>
        <mesh filename="package://assets/top_plate.stl"/>
      </geometry>
    </collision>
    <!-- Part top_plate_2 -->
    <visual>
      <origin xyz="0.246036 0.214246 0.0761185" rpy="7.88861e-31 1.37096e-16 -1.11022e-16"/>
      <geometry>
        <mesh filename="package://assets/top_plate.stl"/>
      </geometry>
      <material name="top_plate_2_material">
        <color rgba="0.615686 0.811765 0.929412 1"/>
      </material>
    </visual>
    <collision>
      <origin xyz="0.246036 0.214246 0.0761185" rpy="7.88861e-31 1.37096e-16 -1.11022e-16"/>
      <geometry>
        <mesh filename="package://assets/top_plate.stl"/>
      </geometry>
    </collision>
    <!-- Part side_plate -->
    <visual>
      <origin xyz="0.245639 -0.0396343 -0.0792903" rpy="1.37096e-16 -7.88861e-31 1.5708"/>
      <geometry>
        <mesh filename="package://assets/side_plate.stl"/>
      </geometry>
      <material name="side_plate_material">
        <color rgba="0.615686 0.811765 0.929412 1"/>
      </material>
    </visual>
    <collision>
      <origin xyz="0.245639 -0.0396343 -0.0792903" rpy="1.37096e-16 -7.88861e-31 1.5708"/>
      <geometry>
        <mesh filename="package://assets/side_plate.stl"/>
      </geometry>
    </collision>
    <!-- Part front_plate -->
    <visual>
      <origin xyz="0.62316 0.21554 -0.0754249" rpy="6.02997e-09 -5.8438e-09 1.5708"/>
      <geometry>
        <mesh filename="package://assets/front_plate.stl"/>
      </geometry>
      <material name="front_plate_material">
        <color rgba="0.615686 0.811765 0.929412 1"/>
      </material>
    </visual>
    <collision>
      <origin xyz="0.62316 0.21554 -0.0754249" rpy="6.02997e-09 -5.8438e-09 1.5708"/>
      <geometry>
        <mesh filename="package://assets/front_plate.stl"/>
      </geometry>
    </collision>
    <!-- Part front_plate_2 -->
    <visual>
      <origin xyz="-0.136203 0.215031 -0.0777626" rpy="1.37096e-16 -7.88861e-31 1.5708"/>
      <geometry>
        <mesh filename="package://assets/front_plate.stl"/>
      </geometry>
      <material name="front_plate_2_material">
        <color rgba="0.615686 0.811765 0.929412 1"/>
      </material>
    </visual>
    <collision>
      <origin xyz="-0.136203 0.215031 -0.0777626" rpy="1.37096e-16 -7.88861e-31 1.5708"/>
      <geometry>
        <mesh filename="package://assets/front_plate.stl"/>
      </geometry>
    </collision>
    <!-- Part side_plate_2 -->
    <visual>
      <origin xyz="0.244856 0.466079 -0.0801256" rpy="1.37096e-16 -7.88861e-31 1.5708"/>
      <geometry>
        <mesh filename="package://assets/side_plate.stl"/>
      </geometry>
      <material name="side_plate_2_material">
        <color rgba="0.615686 0.811765 0.929412 1"/>
      </material>
    </visual>
    <collision>
      <origin xyz="0.244856 0.466079 -0.0801256" rpy="1.37096e-16 -7.88861e-31 1.5708"/>
      <geometry>
        <mesh filename="package://assets/side_plate.stl"/>
      </geometry>
    </collision>
    <!-- Part corner_bracket_8020 -->
    <visual>
      <origin xyz="-0.0957503 -0.0174471 -0.193326" rpy="1.5708 6.23025e-09 -0.0349066"/>
      <geometry>
        <mesh filename="package://assets/corner_bracket_8020.stl"/>
      </geometry>
      <material name="corner_bracket_8020_material">
        <color rgba="1 1 1 1"/>
      </material>
    </visual>
    <collision>
      <origin xyz="-0.0957503 -0.0174471 -0.193326" rpy="1.5708 6.23025e-09 -0.0349066"/>
      <geometry>
        <mesh filename="package://assets/corner_bracket_8020.stl"/>
      </geometry>
    </collision>
    <!-- Part corner_bracket_8020_2 -->
    <visual>
      <origin xyz="-0.0957503 0.446077 0.0370736" rpy="1.53589 1.5708 0"/>
      <geometry>
        <mesh filename="package://assets/corner_bracket_8020.stl"/>
      </geometry>
      <material name="corner_bracket_8020_2_material">
        <color rgba="1 1 1 1"/>
      </material>
    </visual>
    <collision>
      <origin xyz="-0.0957503 0.446077 0.0370736" rpy="1.53589 1.5708 0"/>
      <geometry>
        <mesh filename="package://assets/corner_bracket_8020.stl"/>
      </geometry>
    </collision>
    <!-- Part rover_length_extrusion -->
    <visual>
      <origin xyz="0.129614 -0.0166285 -0.213898" rpy="1.03543e-08 -1.5708 0"/>
      <geometry>
        <mesh filename="package://assets/rover_length_extrusion.stl"/>
      </geometry>
      <material name="rover_length_extrusion_material">
        <color rgba="0.752941 0.752941 0.752941 1"/>
      </material>
    </visual>
    <collision>
      <origin xyz="0.129614 -0.0166285 -0.213898" rpy="1.03543e-08 -1.5708 0"/>
      <geometry>
        <mesh filename="package://assets/rover_length_extrusion.stl"/>
      </geometry>
    </collision>
    <!-- Part corner_bracket_8020_3 -->
    <visual>
      <origin xyz="-0.0950944 0.427162 0.0553401" rpy="3.10669 6.02999e-09 1.03543e-08"/>
      <geometry>
        <mesh filename="package://assets/corner_bracket_8020.stl"/>
      </geometry>
      <material name="corner_bracket_8020_3_material">
        <color rgba="1 1 1 1"/>
      </material>
    </visual>
    <collision>
      <origin xyz="-0.0950944 0.427162 0.0553401" rpy="3.10669 6.02999e-09 1.03543e-08"/>
      <geometry>
        <mesh filename="package://assets/corner_bracket_8020.stl"/>
      </geometry>
    </collision>
    <!-- Part corner_bracket_8020_4 -->
    <visual>
      <origin xyz="-0.0935856 0.00185393 -0.213466" rpy="-3.14159 -0.0349066 1.5708"/>
      <geometry>
        <mesh filename="package://assets/corner_bracket_8020.stl"/>
      </geometry>
      <material name="corner_bracket_8020_4_material">
        <color rgba="1 1 1 1"/>
      </material>
    </visual>
    <collision>
      <origin xyz="-0.0935856 0.00185393 -0.213466" rpy="-3.14159 -0.0349066 1.5708"/>
      <geometry>
        <mesh filename="package://assets/corner_bracket_8020.stl"/>
      </geometry>
    </collision>
    <!-- Part rover_length_extrusion_2 -->
    <visual>
      <origin xyz="0.129614 0.446031 -0.213898" rpy="1.03543e-08 -1.5708 0"/>
      <geometry>
        <mesh filename="package://assets/rover_length_extrusion.stl"/>
      </geometry>
      <material name="rover_length_extrusion_2_material">
        <color rgba="0.752941 0.752941 0.752941 1"/>
      </material>
    </visual>
    <collision>
      <origin xyz="0.129614 0.446031 -0.213898" rpy="1.03543e-08 -1.5708 0"/>
      <geometry>
        <mesh filename="package://assets/rover_length_extrusion.stl"/>
      </geometry>
    </collision>
    <!-- Part corner_bracket_8020_5 -->
    <visual>
      <origin xyz="-0.0957503 -0.0165827 0.0370736" rpy="1.53589 1.5708 0"/>
      <geometry>
        <mesh filename="package://assets/corner_bracket_8020.stl"/>
      </geometry>
      <material name="corner_bracket_8020_5_material">
        <color rgba="1 1 1 1"/>
      </material>
    </visual>
    <collision>
      <origin xyz="-0.0957503 -0.0165827 0.0370736" rpy="1.53589 1.5708 0"/>
      <geometry>
        <mesh filename="package://assets/corner_bracket_8020.stl"/>
      </geometry>
    </collision>
    <!-- Part rover_height_extrusion -->
    <visual>
      <origin xyz="0.604444 -0.0170149 -0.420126" rpy="3.14159 -6.03e-09 -3.14159"/>
      <geometry>
        <mesh filename="package://assets/rover_height_extrusion.stl"/>
      </geometry>
      <material name="rover_height_extrusion_material">
        <color rgba="0.752941 0.752941 0.752941 1"/>
      </material>
    </visual>
    <collision>
      <origin xyz="0.604444 -0.0170149 -0.420126" rpy="3.14159 -6.03e-09 -3.14159"/>
      <geometry>
        <mesh filename="package://assets/rover_height_extrusion.stl"/>
      </geometry>
    </collision>
    <!-- Part corner_bracket_8020_6 -->
    <visual>
      <origin xyz="-0.0935856 0.427548 -0.213466" rpy="3.10669 6.03006e-09 1.03543e-08"/>
      <geometry>
        <mesh filename="package://assets/corner_bracket_8020.stl"/>
      </geometry>
      <material name="corner_bracket_8020_6_material">
        <color rgba="1 1 1 1"/>
      </material>
    </visual>
    <collision>
      <origin xyz="-0.0935856 0.427548 -0.213466" rpy="3.10669 6.03006e-09 1.03543e-08"/>
      <geometry>
        <mesh filename="package://assets/corner_bracket_8020.stl"/>
      </geometry>
    </collision>
    <!-- Part rover_width_extrusion -->
    <visual>
      <origin xyz="-0.112072 0.00770116 -0.213246" rpy="-1.5708 -0.0349066 -3.14159"/>
      <geometry>
        <mesh filename="package://assets/rover_width_extrusion.stl"/>
      </geometry>
      <material name="rover_width_extrusion_material">
        <color rgba="0.752941 0.752941 0.752941 1"/>
      </material>
    </visual>
    <collision>
      <origin xyz="-0.112072 0.00770116 -0.213246" rpy="-1.5708 -0.0349066 -3.14159"/>
      <geometry>
        <mesh filename="package://assets/rover_width_extrusion.stl"/>
      </geometry>
    </collision>
    <!-- Part rover_length_extrusion_3 -->
    <visual>
      <origin xyz="0.128106 0.445645 0.0549079" rpy="1.03543e-08 -1.5708 0"/>
      <geometry>
        <mesh filename="package://assets/rover_length_extrusion.stl"/>
      </geometry>
      <material name="rover_length_extrusion_3_material">
        <color rgba="0.752941 0.752941 0.752941 1"/>
      </material>
    </visual>
    <collision>
      <origin xyz="0.128106 0.445645 0.0549079" rpy="1.03543e-08 -1.5708 0"/>
      <geometry>
        <mesh filename="package://assets/rover_length_extrusion.stl"/>
      </geometry>
    </collision>
    <!-- Part corner_bracket_8020_7 -->
    <visual>
      <origin xyz="0.585306 0.00146761 0.0553401" rpy="3.10669 -6.02999e-09 -3.14159"/>
      <geometry>
        <mesh filename="package://assets/corner_bracket_8020.stl"/>
      </geometry>
      <material name="corner_bracket_8020_7_material">
        <color rgba="1 1 1 1"/>
      </material>
    </visual>
    <collision>
      <origin xyz="0.585306 0.00146761 0.0553401" rpy="3.10669 -6.02999e-09 -3.14159"/>
      <geometry>
        <mesh filename="package://assets/corner_bracket_8020.stl"/>
      </geometry>
    </collision>
    <!-- Part rover_width_extrusion_2 -->
    <visual>
      <origin xyz="0.605301 0.00770116 -0.213246" rpy="-1.5708 0.0349066 -3.14159"/>
      <geometry>
        <mesh filename="package://assets/rover_width_extrusion.stl"/>
      </geometry>
      <material name="rover_width_extrusion_2_material">
        <color rgba="0.752941 0.752941 0.752941 1"/>
      </material>
    </visual>
    <collision>
      <origin xyz="0.605301 0.00770116 -0.213246" rpy="-1.5708 0.0349066 -3.14159"/>
      <geometry>
        <mesh filename="package://assets/rover_width_extrusion.stl"/>
      </geometry>
    </collision>
    <!-- Part corner_bracket_8020_8 -->
    <visual>
      <origin xyz="-0.0957503 0.445212 -0.193326" rpy="1.5708 6.23025e-09 -0.0349066"/>
      <geometry>
        <mesh filename="package://assets/corner_bracket_8020.stl"/>
      </geometry>
      <material name="corner_bracket_8020_8_material">
        <color rgba="1 1 1 1"/>
      </material>
    </visual>
    <collision>
      <origin xyz="-0.0957503 0.445212 -0.193326" rpy="1.5708 6.23025e-09 -0.0349066"/>
      <geometry>
        <mesh filename="package://assets/corner_bracket_8020.stl"/>
      </geometry>
    </collision>
    <!-- Part corner_bracket_8020_9 -->
    <visual>
      <origin xyz="0.585962 0.446077 -0.193326" rpy="1.53589 -1.5708 0"/>
      <geometry>
        <mesh filename="package://assets/corner_bracket_8020.stl"/>
      </geometry>
      <material name="corner_bracket_8020_9_material">
        <color rgba="1 1 1 1"/>
      </material>
    </visual>
    <collision>
      <origin xyz="0.585962 0.446077 -0.193326" rpy="1.53589 -1.5708 0"/>
      <geometry>
        <mesh filename="package://assets/corner_bracket_8020.stl"/>
      </geometry>
    </collision>
    <!-- Part corner_bracket_8020_10 -->
    <visual>
      <origin xyz="0.586814 0.00185394 -0.213466" rpy="3.10669 -6.03006e-09 -3.14159"/>
      <geometry>
        <mesh filename="package://assets/corner_bracket_8020.stl"/>
      </geometry>
      <material name="corner_bracket_8020_10_material">
        <color rgba="1 1 1 1"/>
      </material>
    </visual>
    <collision>
      <origin xyz="0.586814 0.00185394 -0.213466" rpy="3.10669 -6.03006e-09 -3.14159"/>
      <geometry>
        <mesh filename="package://assets/corner_bracket_8020.stl"/>
      </geometry>
    </collision>
    <!-- Part rover_width_extrusion_3 -->
    <visual>
      <origin xyz="-0.113581 0.00731483 0.0555599" rpy="-1.5708 -0.0349066 -3.14159"/>
      <geometry>
        <mesh filename="package://assets/rover_width_extrusion.stl"/>
      </geometry>
      <material name="rover_width_extrusion_3_material">
        <color rgba="0.752941 0.752941 0.752941 1"/>
      </material>
    </visual>
    <collision>
      <origin xyz="-0.113581 0.00731483 0.0555599" rpy="-1.5708 -0.0349066 -3.14159"/>
      <geometry>
        <mesh filename="package://assets/rover_width_extrusion.stl"/>
      </geometry>
    </collision>
    <!-- Part corner_bracket_8020_11 -->
    <visual>
      <origin xyz="0.585962 0.446077 0.0370736" rpy="-1.5708 -6.23027e-09 3.10669"/>
      <geometry>
        <mesh filename="package://assets/corner_bracket_8020.stl"/>
      </geometry>
      <material name="corner_bracket_8020_11_material">
        <color rgba="1 1 1 1"/>
      </material>
    </visual>
    <collision>
      <origin xyz="0.585962 0.446077 0.0370736" rpy="-1.5708 -6.23027e-09 3.10669"/>
      <geometry>
        <mesh filename="package://assets/corner_bracket_8020.stl"/>
      </geometry>
    </collision>
    <!-- Part corner_bracket_8020_12 -->
    <visual>
      <origin xyz="0.586814 0.427548 -0.213466" rpy="3.14159 -0.0349066 -1.5708"/>
      <geometry>
        <mesh filename="package://assets/corner_bracket_8020.stl"/>
      </geometry>
      <material name="corner_bracket_8020_12_material">
        <color rgba="1 1 1 1"/>
      </material>
    </visual>
    <collision>
      <origin xyz="0.586814 0.427548 -0.213466" rpy="3.14159 -0.0349066 -1.5708"/>
      <geometry>
        <mesh filename="package://assets/corner_bracket_8020.stl"/>
      </geometry>
    </collision>
    <!-- Part corner_bracket_8020_13 -->
    <visual>
      <origin xyz="0.585962 -0.0174471 0.0370736" rpy="-1.5708 -5.82239e-09 -3.10669"/>
      <geometry>
        <mesh filename="package://assets/corner_bracket_8020.stl"/>
      </geometry>
      <material name="corner_bracket_8020_13_material">
        <color rgba="1 1 1 1"/>
      </material>
    </visual>
    <collision>
      <origin xyz="0.585962 -0.0174471 0.0370736" rpy="-1.5708 -5.82239e-09 -3.10669"/>
      <geometry>
        <mesh filename="package://assets/corner_bracket_8020.stl"/>
      </geometry>
    </collision>
    <!-- Part corner_bracket_8020_14 -->
    <visual>
      <origin xyz="-0.0950944 0.0014676 0.0553401" rpy="-3.14159 -0.0349066 1.5708"/>
      <geometry>
        <mesh filename="package://assets/corner_bracket_8020.stl"/>
      </geometry>
      <material name="corner_bracket_8020_14_material">
        <color rgba="1 1 1 1"/>
      </material>
    </visual>
    <collision>
      <origin xyz="-0.0950944 0.0014676 0.0553401" rpy="-3.14159 -0.0349066 1.5708"/>
      <geometry>
        <mesh filename="package://assets/corner_bracket_8020.stl"/>
      </geometry>
    </collision>
    <!-- Part rover_height_extrusion_2 -->
    <visual>
      <origin xyz="0.604444 0.445645 -0.420126" rpy="3.14159 -6.03e-09 -3.14159"/>
      <geometry>
        <mesh filename="package://assets/rover_height_extrusion.stl"/>
      </geometry>
      <material name="rover_height_extrusion_2_material">
        <color rgba="0.752941 0.752941 0.752941 1"/>
      </material>
    </visual>
    <collision>
      <origin xyz="0.604444 0.445645 -0.420126" rpy="3.14159 -6.03e-09 -3.14159"/>
      <geometry>
        <mesh filename="package://assets/rover_height_extrusion.stl"/>
      </geometry>
    </collision>
    <!-- Part corner_bracket_8020_15 -->
    <visual>
      <origin xyz="0.585962 -0.0165827 -0.193326" rpy="1.53589 -1.5708 0"/>
      <geometry>
        <mesh filename="package://assets/corner_bracket_8020.stl"/>
      </geometry>
      <material name="corner_bracket_8020_15_material">
        <color rgba="1 1 1 1"/>
      </material>
    </visual>
    <collision>
      <origin xyz="0.585962 -0.0165827 -0.193326" rpy="1.53589 -1.5708 0"/>
      <geometry>
        <mesh filename="package://assets/corner_bracket_8020.stl"/>
      </geometry>
    </collision>
    <!-- Part rover_width_extrusion_4 -->
    <visual>
      <origin xyz="0.603792 0.00731484 0.0555599" rpy="-1.5708 0.0349066 -3.14159"/>
      <geometry>
        <mesh filename="package://assets/rover_width_extrusion.stl"/>
      </geometry>
      <material name="rover_width_extrusion_4_material">
        <color rgba="0.752941 0.752941 0.752941 1"/>
      </material>
    </visual>
    <collision>
      <origin xyz="0.603792 0.00731484 0.0555599" rpy="-1.5708 0.0349066 -3.14159"/>
      <geometry>
        <mesh filename="package://assets/rover_width_extrusion.stl"/>
      </geometry>
    </collision>
    <!-- Part corner_bracket_8020_16 -->
    <visual>
      <origin xyz="0.585306 0.427162 0.0553401" rpy="3.14159 -0.0349066 -1.5708"/>
      <geometry>
        <mesh filename="package://assets/corner_bracket_8020.stl"/>
      </geometry>
      <material name="corner_bracket_8020_16_material">
        <color rgba="1 1 1 1"/>
      </material>
    </visual>
    <collision>
      <origin xyz="0.585306 0.427162 0.0553401" rpy="3.14159 -0.0349066 -1.5708"/>
      <geometry>
        <mesh filename="package://assets/corner_bracket_8020.stl"/>
      </geometry>
    </collision>
    <!-- Part rover_length_extrusion_4 -->
    <visual>
      <origin xyz="0.128106 -0.0170149 0.0549079" rpy="1.03543e-08 -1.5708 0"/>
      <geometry>
        <mesh filename="package://assets/rover_length_extrusion.stl"/>
      </geometry>
      <material name="rover_length_extrusion_4_material">
        <color rgba="0.752941 0.752941 0.752941 1"/>
      </material>
    </visual>
    <collision>
      <origin xyz="0.128106 -0.0170149 0.0549079" rpy="1.03543e-08 -1.5708 0"/>
      <geometry>
        <mesh filename="package://assets/rover_length_extrusion.stl"/>
      </geometry>
    </collision>
    <!-- Part rover_height_extrusion_3 -->
    <visual>
      <origin xyz="-0.114233 -0.0170149 -0.420126" rpy="3.14159 -6.02998e-09 -3.14159"/>
      <geometry>
        <mesh filename="package://assets/rover_height_extrusion.stl"/>
      </geometry>
      <material name="rover_height_extrusion_3_material">
        <color rgba="0.752941 0.752941 0.752941 1"/>
      </material>
    </visual>
    <collision>
      <origin xyz="-0.114233 -0.0170149 -0.420126" rpy="3.14159 -6.02998e-09 -3.14159"/>
      <geometry>
        <mesh filename="package://assets/rover_height_extrusion.stl"/>
      </geometry>
    </collision>
    <!-- Part rover_height_extrusion_4 -->
    <visual>
      <origin xyz="-0.114233 0.445645 -0.420126" rpy="3.14159 -6.02998e-09 -3.14159"/>
      <geometry>
        <mesh filename="package://assets/rover_height_extrusion.stl"/>
      </geometry>
      <material name="rover_height_extrusion_4_material">
        <color rgba="0.752941 0.752941 0.752941 1"/>
      </material>
    </visual>
    <collision>
      <origin xyz="-0.114233 0.445645 -0.420126" rpy="3.14159 -6.02998e-09 -3.14159"/>
      <geometry>
        <mesh filename="package://assets/rover_height_extrusion.stl"/>
      </geometry>
    </collision>
  </link>
  <!-- Link bearing_block -->
  <link name="bearing_block">
    <inertial>
      <origin xyz="0 0 0" rpy="0 0 0"/>
      <mass value="1e-09"/>
      <inertia ixx="1e-09" ixy="0" ixz="0" iyy="1e-09" iyz="0" izz="1e-09"/>
    </inertial>
    <!-- Part part_2 -->
    <visual>
      <origin xyz="0.0159473 -0.000761272 -0.00414236" rpy="1.5708 1.11018e-16 3.13275"/>
      <geometry>
        <mesh filename="package://assets/part_2.stl"/>
      </geometry>
      <material name="part_2_material">
        <color rgba="0.917647 0.917647 0.917647 1"/>
      </material>
    </visual>
    <collision>
      <origin xyz="0.0159473 -0.000761272 -0.00414236" rpy="1.5708 1.11018e-16 3.13275"/>
      <geometry>
        <mesh filename="package://assets/part_2.stl"/>
      </geometry>
    </collision>
    <!-- Part part_1 -->
    <visual>
      <origin xyz="-1.66533e-16 0 -0.00705559" rpy="1.5708 1.11018e-16 3.13275"/>
      <geometry>
        <mesh filename="package://assets/part_1.stl"/>
      </geometry>
      <material name="part_1_material">
        <color rgba="0.615686 0.811765 0.929412 1"/>
      </material>
    </visual>
    <collision>
      <origin xyz="-1.66533e-16 0 -0.00705559" rpy="1.5708 1.11018e-16 3.13275"/>
      <geometry>
        <mesh filename="package://assets/part_1.stl"/>
      </geometry>
    </collision>
    <!-- Part part_3 -->
    <visual>
      <origin xyz="-1.66533e-16 0 -0.00705559" rpy="1.5708 1.11018e-16 3.13275"/>
      <geometry>
        <mesh filename="package://assets/part_3.stl"/>
      </geometry>
      <material name="part_3_material">
        <color rgba="0.972549 0.529412 0.00392157 1"/>
      </material>
    </visual>
    <collision>
      <origin xyz="-1.66533e-16 0 -0.00705559" rpy="1.5708 1.11018e-16 3.13275"/>
      <geometry>
        <mesh filename="package://assets/part_3.stl"/>
      </geometry>
    </collision>
    <!-- Part part_9 -->
    <visual>
      <origin xyz="0.0159473 -0.000761272 -0.00414236" rpy="1.5708 1.11018e-16 3.13275"/>
      <geometry>
        <mesh filename="package://assets/part_9.stl"/>
      </geometry>
      <material name="part_9_material">
        <color rgba="0.231373 0.380392 0.705882 1"/>
      </material>
    </visual>
    <collision>
      <origin xyz="0.0159473 -0.000761272 -0.00414236" rpy="1.5708 1.11018e-16 3.13275"/>
      <geometry>
        <mesh filename="package://assets/part_9.stl"/>
      </geometry>
    </collision>
    <!-- Part part1 -->
    <visual>
      <origin xyz="0.10133 -0.0356448 -0.0164915" rpy="1.5708 -4.42446e-17 1.16089"/>
      <geometry>
        <mesh filename="package://assets/part1.stl"/>
      </geometry>
      <material name="part1_material">
        <color rgba="0.231373 0.380392 0.705882 1"/>
      </material>
    </visual>
    <collision>
      <origin xyz="0.10133 -0.0356448 -0.0164915" rpy="1.5708 -4.42446e-17 1.16089"/>
      <geometry>
        <mesh filename="package://assets/part1.stl"/>
      </geometry>
    </collision>
    <!-- Part part_1_2 -->
    <visual>
      <origin xyz="0.241907 -0.19275 -0.0270556" rpy="7.78075e-17 7.9196e-17 -2.36504"/>
      <geometry>
        <mesh filename="package://assets/part_1__2.stl"/>
      </geometry>
      <material name="part_1_2_material">
        <color rgba="0.615686 0.811765 0.929412 1"/>
      </material>
    </visual>
    <collision>
      <origin xyz="0.241907 -0.19275 -0.0270556" rpy="7.78075e-17 7.9196e-17 -2.36504"/>
      <geometry>
        <mesh filename="package://assets/part_1__2.stl"/>
      </geometry>
    </collision>
    <!-- Part part1_2 -->
    <visual>
      <origin xyz="-0.150396 -0.0336933 -0.0137249" rpy="1.5708 -4.1144e-17 -1.19115"/>
      <geometry>
        <mesh filename="package://assets/part1.stl"/>
      </geometry>
      <material name="part1_2_material">
        <color rgba="0.231373 0.380392 0.705882 1"/>
      </material>
    </visual>
    <collision>
      <origin xyz="-0.150396 -0.0336933 -0.0137249" rpy="1.5708 -4.1144e-17 -1.19115"/>
      <geometry>
        <mesh filename="package://assets/part1.stl"/>
      </geometry>
    </collision>
    <!-- Part bearing_block -->
    <visual>
      <origin xyz="-2.77556e-17 0 -0.00705559" rpy="1.5708 1.11018e-16 3.13275"/>
      <geometry>
        <mesh filename="package://assets/bearing_block.stl"/>
      </geometry>
      <material name="bearing_block_material">
        <color rgba="0.647059 0.647059 0.647059 1"/>
      </material>
    </visual>
    <collision>
      <origin xyz="-2.77556e-17 0 -0.00705559" rpy="1.5708 1.11018e-16 3.13275"/>
      <geometry>
        <mesh filename="package://assets/bearing_block.stl"/>
      </geometry>
    </collision>
  </link>
  <!-- Link part_1 -->
  <link name="part_1">
    <inertial>
      <origin xyz="0 0 0" rpy="0 0 0"/>
      <mass value="1e-09"/>
      <inertia ixx="1e-09" ixy="0" ixz="0" iyy="1e-09" iyz="0" izz="1e-09"/>
    </inertial>
    <!-- Part part_2_2 -->
    <visual>
      <origin xyz="2.77556e-17 0 0" rpy="-3.14159 1.25836e-32 4.12467e-17"/>
      <geometry>
        <mesh filename="package://assets/part_2__2.stl"/>
      </geometry>
      <material name="part_2_2_material">
        <color rgba="0.647059 0.647059 0.647059 1"/>
      </material>
    </visual>
    <collision>
      <origin xyz="2.77556e-17 0 0" rpy="-3.14159 1.25836e-32 4.12467e-17"/>
      <geometry>
        <mesh filename="package://assets/part_2__2.stl"/>
      </geometry>
    </collision>
    <!-- Part part_1_3 -->
    <visual>
      <origin xyz="2.77556e-17 0 0" rpy="-3.14159 1.25836e-32 4.12467e-17"/>
      <geometry>
        <mesh filename="package://assets/part_1__3.stl"/>
      </geometry>
      <material name="part_1_3_material">
        <color rgba="0.615686 0.811765 0.929412 1"/>
      </material>
    </visual>
    <collision>
      <origin xyz="2.77556e-17 0 0" rpy="-3.14159 1.25836e-32 4.12467e-17"/>
      <geometry>
        <mesh filename="package://assets/part_1__3.stl"/>
      </geometry>
    </collision>
  </link>
  <!-- Joint from bearing_block to part_1 -->
  <joint name="wheel_6" type="continuous">
    <origin xyz="0.296572 -0.248391 -0.0270556" rpy="8.02313e-17 7.67391e-17 -2.33395"/>
    <parent link="bearing_block"/>
    <child link="part_1"/>
    <axis xyz="0 0 1"/>
    <limit effort="10" velocity="10"/>
  </joint>
  <!-- Joint from front_plate to bearing_block -->
  <joint name="main_r" type="revolute">
    <origin xyz="0.245655 -0.0396343 -0.0792902" rpy="1.5708 -1.37096e-16 -3.14159"/>
    <parent link="front_plate"/>
    <child link="bearing_block"/>
    <axis xyz="0 0 1"/>
    <limit effort="10" velocity="10" lower="-3.141592653589793" upper="3.141592653589793"/>
  </joint>
  <!-- Link part_9 -->
  <link name="part_9">
    <inertial>
      <origin xyz="0 0 0" rpy="0 0 0"/>
      <mass value="1e-09"/>
      <inertia ixx="1e-09" ixy="0" ixz="0" iyy="1e-09" iyz="0" izz="1e-09"/>
    </inertial>
    <!-- Part part_9_2 -->
    <visual>
      <origin xyz="-0.0159534 -0.000620172 -0.0199132" rpy="-1.5708 3.27328e-31 -7.81868e-16"/>
      <geometry>
        <mesh filename="package://assets/part_9.stl"/>
      </geometry>
      <material name="part_9_2_material">
        <color rgba="0.231373 0.380392 0.705882 1"/>
      </material>
    </visual>
    <collision>
      <origin xyz="-0.0159534 -0.000620172 -0.0199132" rpy="-1.5708 3.27328e-31 -7.81868e-16"/>
      <geometry>
        <mesh filename="package://assets/part_9.stl"/>
      </geometry>
    </collision>
    <!-- Part part_1_4 -->
    <visual>
      <origin xyz="4.44089e-16 -1.38778e-17 -0.02" rpy="-1.5708 -5.47265e-33 2.15161e-16"/>
      <geometry>
        <mesh filename="package://assets/part_1.stl"/>
      </geometry>
      <material name="part_1_4_material">
        <color rgba="0.615686 0.811765 0.929412 1"/>
      </material>
    </visual>
    <collision>
      <origin xyz="4.44089e-16 -1.38778e-17 -0.02" rpy="-1.5708 -5.47265e-33 2.15161e-16"/>
      <geometry>
        <mesh filename="package://assets/part_1.stl"/>
      </geometry>
    </collision>
    <!-- Part part1_3 -->
    <visual>
      <origin xyz="-0.101641 -0.034747 -0.0105641" rpy="-1.5708 -5.94946e-31 1.97185"/>
      <geometry>
        <mesh filename="package://assets/part1.stl"/>
      </geometry>
      <material name="part1_3_material">
        <color rgba="0.231373 0.380392 0.705882 1"/>
      </material>
    </visual>
    <collision>
      <origin xyz="-0.101641 -0.034747 -0.0105641" rpy="-1.5708 -5.94946e-31 1.97185"/>
      <geometry>
        <mesh filename="package://assets/part1.stl"/>
      </geometry>
    </collision>
    <!-- Part part_3_2 -->
    <visual>
      <origin xyz="6.66134e-16 5.55112e-17 -0.02" rpy="-1.5708 6.8533e-33 2.28947e-16"/>
      <geometry>
        <mesh filename="package://assets/part_3.stl"/>
      </geometry>
      <material name="part_3_2_material">
        <color rgba="0.972549 0.529412 0.00392157 1"/>
      </material>
    </visual>
    <collision>
      <origin xyz="6.66134e-16 5.55112e-17 -0.02" rpy="-1.5708 6.8533e-33 2.28947e-16"/>
      <geometry>
        <mesh filename="package://assets/part_3.stl"/>
      </geometry>
    </collision>
    <!-- Part part1_4 -->
    <visual>
      <origin xyz="0.150092 -0.0350223 -0.0133306" rpy="-1.5708 6.02428e-31 -1.95929"/>
      <geometry>
        <mesh filename="package://assets/part1.stl"/>
      </geometry>
      <material name="part1_4_material">
        <color rgba="0.231373 0.380392 0.705882 1"/>
      </material>
    </visual>
    <collision>
      <origin xyz="0.150092 -0.0350223 -0.0133306" rpy="-1.5708 6.02428e-31 -1.95929"/>
      <geometry>
        <mesh filename="package://assets/part1.stl"/>
      </geometry>
    </collision>
    <!-- Part bearing_block_2 -->
    <visual>
      <origin xyz="-2.77556e-17 0 -0.02" rpy="-1.5708 -5.47265e-33 4.33351e-18"/>
      <geometry>
        <mesh filename="package://assets/bearing_block.stl"/>
      </geometry>
      <material name="bearing_block_2_material">
        <color rgba="0.647059 0.647059 0.647059 1"/>
      </material>
    </visual>
    <collision>
      <origin xyz="-2.77556e-17 0 -0.02" rpy="-1.5708 -5.47265e-33 4.33351e-18"/>
      <geometry>
        <mesh filename="package://assets/bearing_block.stl"/>
      </geometry>
    </collision>
    <!-- Part part_2_3 -->
    <visual>
      <origin xyz="-0.0159534 -0.000620172 -0.0199132" rpy="-1.5708 -5.47265e-33 2.15161e-16"/>
      <geometry>
        <mesh filename="package://assets/part_2.stl"/>
      </geometry>
      <material name="part_2_3_material">
        <color rgba="0.917647 0.917647 0.917647 1"/>
      </material>
    </visual>
    <collision>
      <origin xyz="-0.0159534 -0.000620172 -0.0199132" rpy="-1.5708 -5.47265e-33 2.15161e-16"/>
      <geometry>
        <mesh filename="package://assets/part_2.stl"/>
      </geometry>
    </collision>
    <!-- Part part_1_5 -->
    <visual>
      <origin xyz="-0.243603 -0.190603 -0.02" rpy="-3.19617e-31 -5.98e-31 2.35619"/>
      <geometry>
        <mesh filename="package://assets/part_1__2.stl"/>
      </geometry>
      <material name="part_1_5_material">
        <color rgba="0.615686 0.811765 0.929412 1"/>
      </material>
    </visual>
    <collision>
      <origin xyz="-0.243603 -0.190603 -0.02" rpy="-3.19617e-31 -5.98e-31 2.35619"/>
      <geometry>
        <mesh filename="package://assets/part_1__2.stl"/>
      </geometry>
    </collision>
  </link>
  <!-- Link part1 -->
  <link name="part1">
    <inertial>
      <origin xyz="0 0 0" rpy="0 0 0"/>
      <mass value="1e-09"/>
      <inertia ixx="1e-09" ixy="0" ixz="0" iyy="1e-09" iyz="0" izz="1e-09"/>
    </inertial>
    <!-- Part part_11 -->
    <visual>
      <origin xyz="-0.240889 0.120301 -0.04" rpy="-1.5708 3.48009e-24 -0.0826644"/>
      <geometry>
        <mesh filename="package://assets/part_11.stl"/>
      </geometry>
      <material name="part_11_material">
        <color rgba="0.980392 0.713725 0.00392157 1"/>
      </material>
    </visual>
    <collision>
      <origin xyz="-0.240889 0.120301 -0.04" rpy="-1.5708 3.48009e-24 -0.0826644"/>
      <geometry>
        <mesh filename="package://assets/part_11.stl"/>
      </geometry>
    </collision>
    <!-- Part part_6 -->
    <visual>
      <origin xyz="0.0492653 -0.204145 0.0229132" rpy="1.5708 5.40533e-24 1.48813"/>
      <geometry>
        <mesh filename="package://assets/part_6.stl"/>
      </geometry>
      <material name="part_6_material">
        <color rgba="0.972549 0.529412 0.00392157 1"/>
      </material>
    </visual>
    <collision>
      <origin xyz="0.0492653 -0.204145 0.0229132" rpy="1.5708 5.40533e-24 1.48813"/>
      <geometry>
        <mesh filename="package://assets/part_6.stl"/>
      </geometry>
    </collision>
    <!-- Part part_12 -->
    <visual>
      <origin xyz="-0.242334 0.120421 -0.04" rpy="-1.5708 3.48009e-24 -0.0826644"/>
      <geometry>
        <mesh filename="package://assets/part_12.stl"/>
      </geometry>
      <material name="part_12_material">
        <color rgba="0.615686 0.811765 0.929412 1"/>
      </material>
    </visual>
    <collision>
      <origin xyz="-0.242334 0.120421 -0.04" rpy="-1.5708 3.48009e-24 -0.0826644"/>
      <geometry>
        <mesh filename="package://assets/part_12.stl"/>
      </geometry>
    </collision>
    <!-- Part part_1_6 -->
    <visual>
      <origin xyz="0.120688 -0.100291 -0.0170868" rpy="-1.11022e-16 -3.92523e-17 -2.43886"/>
      <geometry>
        <mesh filename="package://assets/part_1__2.stl"/>
      </geometry>
      <material name="part_1_6_material">
        <color rgba="0.615686 0.811765 0.929412 1"/>
      </material>
    </visual>
    <collision>
      <origin xyz="0.120688 -0.100291 -0.0170868" rpy="-1.11022e-16 -3.92523e-17 -2.43886"/>
      <geometry>
        <mesh filename="package://assets/part_1__2.stl"/>
      </geometry>
    </collision>
    <!-- Part part1_5 -->
    <visual>
      <origin xyz="-0.0893887 -0.0295956 -0.00802691" rpy="-1.5708 3.88909e-24 1.8372"/>
      <geometry>
        <mesh filename="package://assets/part1.stl"/>
      </geometry>
      <material name="part1_5_material">
        <color rgba="0.231373 0.380392 0.705882 1"/>
      </material>
    </visual>
    <collision>
      <origin xyz="-0.0893887 -0.0295956 -0.00802691" rpy="-1.5708 3.88909e-24 1.8372"/>
      <geometry>
        <mesh filename="package://assets/part1.stl"/>
      </geometry>
    </collision>
    <!-- Part part_5 -->
    <visual>
      <origin xyz="-0.240889 0.120301 -0.04" rpy="-1.5708 3.48009e-24 -0.0826644"/>
      <geometry>
        <mesh filename="package://assets/part_5.stl"/>
      </geometry>
      <material name="part_5_material">
        <color rgba="0.768627 0.886275 0.952941 1"/>
      </material>
    </visual>
    <collision>
      <origin xyz="-0.240889 0.120301 -0.04" rpy="-1.5708 3.48009e-24 -0.0826644"/>
      <geometry>
        <mesh filename="package://assets/part_5.stl"/>
      </geometry>
    </collision>
    <!-- Part part1_6 -->
    <visual>
      <origin xyz="0.0842756 -0.0421079 -0.00786803" rpy="-1.5708 -6.26961e-24 -2.00253"/>
      <geometry>
        <mesh filename="package://assets/part1.stl"/>
      </geometry>
      <material name="part1_6_material">
        <color rgba="0.231373 0.380392 0.705882 1"/>
      </material>
    </visual>
    <collision>
      <origin xyz="0.0842756 -0.0421079 -0.00786803" rpy="-1.5708 -6.26961e-24 -2.00253"/>
      <geometry>
        <mesh filename="package://assets/part1.stl"/>
      </geometry>
    </collision>
    <!-- Part part_1_7 -->
    <visual>
      <origin xyz="-0.131654 -0.0793832 -0.0170868" rpy="6.28294e-24 1.36108e-24 2.27353"/>
      <geometry>
        <mesh filename="package://assets/part_1__4.stl"/>
      </geometry>
      <material name="part_1_7_material">
        <color rgba="0.615686 0.811765 0.929412 1"/>
      </material>
    </visual>
    <collision>
      <origin xyz="-0.131654 -0.0793832 -0.0170868" rpy="6.28294e-24 1.36108e-24 2.27353"/>
      <geometry>
        <mesh filename="package://assets/part_1__4.stl"/>
      </geometry>
    </collision>
    <!-- Part part_7 -->
    <visual>
      <origin xyz="-0.252844 0.121914 -0.0370868" rpy="-1.5708 3.48009e-24 -0.0826644"/>
      <geometry>
        <mesh filename="package://assets/part_7.stl"/>
      </geometry>
      <material name="part_7_material">
        <color rgba="0.498039 0.498039 0.498039 1"/>
      </material>
    </visual>
    <collision>
      <origin xyz="-0.252844 0.121914 -0.0370868" rpy="-1.5708 3.48009e-24 -0.0826644"/>
      <geometry>
        <mesh filename="package://assets/part_7.stl"/>
      </geometry>
    </collision>
  </link>
  <!-- Link part_4 -->
  <link name="part_4">
    <inertial>
      <origin xyz="0 0 0" rpy="0 0 0"/>
      <mass value="1e-09"/>
      <inertia ixx="1e-09" ixy="0" ixz="0" iyy="1e-09" iyz="0" izz="1e-09"/>
    </inertial>
    <!-- Part part_10 -->
    <visual>
      <origin xyz="-0.361075 -0.113401 0" rpy="1.5708 1.14871e-23 0.0369093"/>
      <geometry>
        <mesh filename="package://assets/part_10.stl"/>
      </geometry>
      <material name="part_10_material">
        <color rgba="0.917647 0.917647 0.917647 1"/>
      </material>
    </visual>
    <collision>
      <origin xyz="-0.361075 -0.113401 0" rpy="1.5708 1.14871e-23 0.0369093"/>
      <geometry>
        <mesh filename="package://assets/part_10.stl"/>
      </geometry>
    </collision>
    <!-- Part part_4 -->
    <visual>
      <origin xyz="-0.361075 -0.113401 1.11022e-16" rpy="1.5708 2.77556e-16 0.0369093"/>
      <geometry>
        <mesh filename="package://assets/part_4.stl"/>
      </geometry>
      <material name="part_4_material">
        <color rgba="0.498039 0.498039 0.498039 1"/>
      </material>
    </visual>
    <collision>
      <origin xyz="-0.361075 -0.113401 1.11022e-16" rpy="1.5708 2.77556e-16 0.0369093"/>
      <geometry>
        <mesh filename="package://assets/part_4.stl"/>
      </geometry>
    </collision>
    <!-- Part part_1_8 -->
    <visual>
      <origin xyz="0.0390951 -0.110633 -0.28" rpy="1.60771 -1.5708 0"/>
      <geometry>
        <mesh filename="package://assets/part_1__5.stl"/>
      </geometry>
      <material name="part_1_8_material">
        <color rgba="0.615686 0.811765 0.929412 1"/>
      </material>
    </visual>
    <collision>
      <origin xyz="0.0390951 -0.110633 -0.28" rpy="1.60771 -1.5708 0"/>
      <geometry>
        <mesh filename="package://assets/part_1__5.stl"/>
      </geometry>
    </collision>
    <!-- Part part_10_2 -->
    <visual>
      <origin xyz="-0.361075 -0.113401 -0.54" rpy="1.5708 1.14871e-23 0.0369093"/>
      <geometry>
        <mesh filename="package://assets/part_10.stl"/>
      </geometry>
      <material name="part_10_2_material">
        <color rgba="0.917647 0.917647 0.917647 1"/>
      </material>
    </visual>
    <collision>
      <origin xyz="-0.361075 -0.113401 -0.54" rpy="1.5708 1.14871e-23 0.0369093"/>
      <geometry>
        <mesh filename="package://assets/part_10.stl"/>
      </geometry>
    </collision>
    <!-- Part part_4_2 -->
    <visual>
      <origin xyz="-0.361075 -0.113401 -0.54" rpy="1.5708 2.77556e-16 0.0369093"/>
      <geometry>
        <mesh filename="package://assets/part_4.stl"/>
      </geometry>
      <material name="part_4_2_material">
        <color rgba="0.498039 0.498039 0.498039 1"/>
      </material>
    </visual>
    <collision>
      <origin xyz="-0.361075 -0.113401 -0.54" rpy="1.5708 2.77556e-16 0.0369093"/>
      <geometry>
        <mesh filename="package://assets/part_4.stl"/>
      </geometry>
    </collision>
  </link>
  <!-- Link part_5 -->
  <link name="part_5">
    <inertial>
      <origin xyz="0 0 0" rpy="0 0 0"/>
      <mass value="1e-09"/>
      <inertia ixx="1e-09" ixy="0" ixz="0" iyy="1e-09" iyz="0" izz="1e-09"/>
    </inertial>
    <!-- Part part_11_2 -->
    <visual>
      <origin xyz="-0.374432 -0.0444928 0.02" rpy="1.5708 3.83049e-24 -0.150144"/>
      <geometry>
        <mesh filename="package://assets/part_11.stl"/>
      </geometry>
      <material name="part_11_2_material">
        <color rgba="0.980392 0.713725 0.00392157 1"/>
      </material>
    </visual>
    <collision>
      <origin xyz="-0.374432 -0.0444928 0.02" rpy="1.5708 3.83049e-24 -0.150144"/>
      <geometry>
        <mesh filename="package://assets/part_11.stl"/>
      </geometry>
    </collision>
    <!-- Part part_1_9 -->
    <visual>
      <origin xyz="-0.222074 0.124603 -0.0229132" rpy="-1.32519e-24 6.74232e-24 0.635254"/>
      <geometry>
        <mesh filename="package://assets/part_1__4.stl"/>
      </geometry>
      <material name="part_1_9_material">
        <color rgba="0.615686 0.811765 0.929412 1"/>
      </material>
    </visual>
    <collision>
      <origin xyz="-0.222074 0.124603 -0.0229132" rpy="-1.32519e-24 6.74232e-24 0.635254"/>
      <geometry>
        <mesh filename="package://assets/part_1__4.stl"/>
      </geometry>
    </collision>
    <!-- Part part_6_2 -->
    <visual>
      <origin xyz="-0.358751 -0.0474923 0.0170868" rpy="1.5708 3.83049e-24 -0.150144"/>
      <geometry>
        <mesh filename="package://assets/part_6.stl"/>
      </geometry>
      <material name="part_6_2_material">
        <color rgba="0.972549 0.529412 0.00392157 1"/>
      </material>
    </visual>
    <collision>
      <origin xyz="-0.358751 -0.0474923 0.0170868" rpy="1.5708 3.83049e-24 -0.150144"/>
      <geometry>
        <mesh filename="package://assets/part_6.stl"/>
      </geometry>
    </collision>
    <!-- Part part1_7 -->
    <visual>
      <origin xyz="-0.0205696 0.0385156 -0.012132" rpy="1.5708 4.05046e-24 1.76972"/>
      <geometry>
        <mesh filename="package://assets/part1.stl"/>
      </geometry>
      <material name="part1_7_material">
        <color rgba="0.231373 0.380392 0.705882 1"/>
      </material>
    </visual>
    <collision>
      <origin xyz="-0.0205696 0.0385156 -0.012132" rpy="1.5708 4.05046e-24 1.76972"/>
      <geometry>
        <mesh filename="package://assets/part1.stl"/>
      </geometry>
    </collision>
    <!-- Part part_5_2 -->
    <visual>
      <origin xyz="-0.374432 -0.0444928 0.02" rpy="1.5708 3.83049e-24 -0.150144"/>
      <geometry>
        <mesh filename="package://assets/part_5.stl"/>
      </geometry>
      <material name="part_5_2_material">
        <color rgba="0.768627 0.886275 0.952941 1"/>
      </material>
    </visual>
    <collision>
      <origin xyz="-0.374432 -0.0444928 0.02" rpy="1.5708 3.83049e-24 -0.150144"/>
      <geometry>
        <mesh filename="package://assets/part_5.stl"/>
      </geometry>
    </collision>
    <!-- Part part1_8 -->
    <visual>
      <origin xyz="-0.192436 0.0664072 -0.0119731" rpy="1.5708 -6.67067e-24 -2.07001"/>
      <geometry>
        <mesh filename="package://assets/part1.stl"/>
      </geometry>
      <material name="part1_8_material">
        <color rgba="0.231373 0.380392 0.705882 1"/>
      </material>
    </visual>
    <collision>
      <origin xyz="-0.192436 0.0664072 -0.0119731" rpy="1.5708 -6.67067e-24 -2.07001"/>
      <geometry>
        <mesh filename="package://assets/part1.stl"/>
      </geometry>
    </collision>
    <!-- Part part_12_2 -->
    <visual>
      <origin xyz="-0.375865 -0.0442759 0.02" rpy="1.5708 3.83049e-24 -0.150144"/>
      <geometry>
        <mesh filename="package://assets/part_12.stl"/>
      </geometry>
      <material name="part_12_2_material">
        <color rgba="0.615686 0.811765 0.929412 1"/>
      </material>
    </visual>
    <collision>
      <origin xyz="-0.375865 -0.0442759 0.02" rpy="1.5708 3.83049e-24 -0.150144"/>
      <geometry>
        <mesh filename="package://assets/part_12.stl"/>
      </geometry>
    </collision>
    <!-- Part part_7_2 -->
    <visual>
      <origin xyz="-0.386436 -0.043304 0.0170868" rpy="1.5708 3.83049e-24 -0.150144"/>
      <geometry>
        <mesh filename="package://assets/part_7.stl"/>
      </geometry>
      <material name="part_7_2_material">
        <color rgba="0.498039 0.498039 0.498039 1"/>
      </material>
    </visual>
    <collision>
      <origin xyz="-0.386436 -0.043304 0.0170868" rpy="1.5708 3.83049e-24 -0.150144"/>
      <geometry>
        <mesh filename="package://assets/part_7.stl"/>
      </geometry>
    </collision>
    <!-- Part part_1_10 -->
    <visual>
      <origin xyz="0.0282834 0.0867279 -0.0229132" rpy="-6.74232e-24 -1.32519e-24 -0.935542"/>
      <geometry>
        <mesh filename="package://assets/part_1__2.stl"/>
      </geometry>
      <material name="part_1_10_material">
        <color rgba="0.615686 0.811765 0.929412 1"/>
      </material>
    </visual>
    <collision>
      <origin xyz="0.0282834 0.0867279 -0.0229132" rpy="-6.74232e-24 -1.32519e-24 -0.935542"/>
      <geometry>
        <mesh filename="package://assets/part_1__2.stl"/>
      </geometry>
    </collision>
  </link>
  <!-- Link part_1_3 -->
  <link name="part_1_3">
    <inertial>
      <origin xyz="0 0 0" rpy="0 0 0"/>
      <mass value="1e-09"/>
      <inertia ixx="1e-09" ixy="0" ixz="0" iyy="1e-09" iyz="0" izz="1e-09"/>
    </inertial>
    <!-- Part part_2_6 -->
    <visual>
      <origin xyz="-6.93889e-18 0 0" rpy="3.14159 -3.02078e-33 6.88259e-17"/>
      <geometry>
        <mesh filename="package://assets/part_2__2.stl"/>
      </geometry>
      <material name="part_2_6_material">
        <color rgba="0.647059 0.647059 0.647059 1"/>
      </material>
    </visual>
    <collision>
      <origin xyz="-6.93889e-18 0 0" rpy="3.14159 -3.02078e-33 6.88259e-17"/>
      <geometry>
        <mesh filename="package://assets/part_2__2.stl"/>
      </geometry>
    </collision>
    <!-- Part part_1_14 -->
    <visual>
      <origin xyz="-6.93889e-18 0 0" rpy="3.14159 -3.02078e-33 6.88259e-17"/>
      <geometry>
        <mesh filename="package://assets/part_1__3.stl"/>
      </geometry>
      <material name="part_1_14_material">
        <color rgba="0.615686 0.811765 0.929412 1"/>
      </material>
    </visual>
    <collision>
      <origin xyz="-6.93889e-18 0 0" rpy="3.14159 -3.02078e-33 6.88259e-17"/>
      <geometry>
        <mesh filename="package://assets/part_1__3.stl"/>
      </geometry>
    </collision>
  </link>
  <!-- Joint from part_5 to part_1_3 -->
  <joint name="wheel_5" type="continuous">
    <origin xyz="-0.268358 0.187387 -0.0229132" rpy="-9.99222e-17 -6.75354e-17 2.42953"/>
    <parent link="part_5"/>
    <child link="part_1_3"/>
    <axis xyz="0 0 1"/>
    <limit effort="10" velocity="10"/>
  </joint>
  <!-- Link part_1_4 -->
  <link name="part_1_4">
    <inertial>
      <origin xyz="0 0 0" rpy="0 0 0"/>
      <mass value="1e-09"/>
      <inertia ixx="1e-09" ixy="0" ixz="0" iyy="1e-09" iyz="0" izz="1e-09"/>
    </inertial>
    <!-- Part part_1_15 -->
    <visual>
      <origin xyz="1.38778e-17 0 0" rpy="-3.14159 -4.87461e-33 6.18592e-17"/>
      <geometry>
        <mesh filename="package://assets/part_1__3.stl"/>
      </geometry>
      <material name="part_1_15_material">
        <color rgba="0.615686 0.811765 0.929412 1"/>
      </material>
    </visual>
    <collision>
      <origin xyz="1.38778e-17 0 0" rpy="-3.14159 -4.87461e-33 6.18592e-17"/>
      <geometry>
        <mesh filename="package://assets/part_1__3.stl"/>
      </geometry>
    </collision>
    <!-- Part part_2_7 -->
    <visual>
      <origin xyz="1.38778e-17 0 0" rpy="-3.14159 -4.87461e-33 6.18592e-17"/>
      <geometry>
        <mesh filename="package://assets/part_2__2.stl"/>
      </geometry>
      <material name="part_2_7_material">
        <color rgba="0.647059 0.647059 0.647059 1"/>
      </material>
    </visual>
    <collision>
      <origin xyz="1.38778e-17 0 0" rpy="-3.14159 -4.87461e-33 6.18592e-17"/>
      <geometry>
        <mesh filename="package://assets/part_2__2.stl"/>
      </geometry>
    </collision>
  </link>
  <!-- Joint from part_5 to part_1_4 -->
  <joint name="wheel_4" type="continuous">
    <origin xyz="0.0910672 0.133012 -0.0229132" rpy="2.95439e-17 2.43899e-18 -1.23566"/>
    <parent link="part_5"/>
    <child link="part_1_4"/>
    <axis xyz="0 0 1"/>
    <limit effort="10" velocity="10"/>
  </joint>
  <!-- Joint from part_4 to part_5 -->
  <joint name="sub2_r" type="revolute">
    <origin xyz="-3.33067e-16 0 -0.56" rpy="7.62338e-24 1.14871e-23 0.0369093"/>
    <parent link="part_4"/>
    <child link="part_5"/>
    <axis xyz="0 0 1"/>
    <limit effort="10" velocity="10" lower="-3.141592653589793" upper="3.141592653589793"/>
  </joint>
  <!-- Joint from part1 to part_4 -->
  <joint name="sub2_l" type="revolute">
    <origin xyz="0.113176 -0.00937701 -1.30048e-09" rpy="3.14159 3.48009e-24 -0.0826644"/>
    <parent link="part1"/>
    <child link="part_4"/>
    <axis xyz="0 0 1"/>
    <limit effort="10" velocity="10" lower="-3.141592653589793" upper="3.141592653589793"/>
  </joint>
  <!-- Link part_1_5 -->
  <link name="part_1_5">
    <inertial>
      <origin xyz="0 0 0" rpy="0 0 0"/>
      <mass value="1e-09"/>
      <inertia ixx="1e-09" ixy="0" ixz="0" iyy="1e-09" iyz="0" izz="1e-09"/>
    </inertial>
    <!-- Part part_1_16 -->
    <visual>
      <origin xyz="-5.55112e-17 -1.11022e-16 0" rpy="-3.14159 -6.33381e-33 -1.7911e-17"/>
      <geometry>
        <mesh filename="package://assets/part_1__3.stl"/>
      </geometry>
      <material name="part_1_16_material">
        <color rgba="0.615686 0.811765 0.929412 1"/>
      </material>
    </visual>
    <collision>
      <origin xyz="-5.55112e-17 -1.11022e-16 0" rpy="-3.14159 -6.33381e-33 -1.7911e-17"/>
      <geometry>
        <mesh filename="package://assets/part_1__3.stl"/>
      </geometry>
    </collision>
    <!-- Part part_2_8 -->
    <visual>
      <origin xyz="-5.55112e-17 -1.11022e-16 0" rpy="-3.14159 -6.33381e-33 -1.7911e-17"/>
      <geometry>
        <mesh filename="package://assets/part_2__2.stl"/>
      </geometry>
      <material name="part_2_8_material">
        <color rgba="0.647059 0.647059 0.647059 1"/>
      </material>
    </visual>
    <collision>
      <origin xyz="-5.55112e-17 -1.11022e-16 0" rpy="-3.14159 -6.33381e-33 -1.7911e-17"/>
      <geometry>
        <mesh filename="package://assets/part_2__2.stl"/>
      </geometry>
    </collision>
  </link>
  <!-- Joint from part1 to part_1_5 -->
  <joint name="wheel_3" type="continuous">
    <origin xyz="0.171099 -0.159811 -0.0170868" rpy="2.61297e-16 -3.92524e-17 0.672719"/>
    <parent link="part1"/>
    <child link="part_1_5"/>
    <axis xyz="0 0 1"/>
    <limit effort="10" velocity="10"/>
  </joint>
  <!-- Link part_1_6 -->
  <link name="part_1_6">
    <inertial>
      <origin xyz="0 0 0" rpy="0 0 0"/>
      <mass value="1e-09"/>
      <inertia ixx="1e-09" ixy="0" ixz="0" iyy="1e-09" iyz="0" izz="1e-09"/>
    </inertial>
    <!-- Part part_1_17 -->
    <visual>
      <origin xyz="0 3.1225e-17 0" rpy="3.14159 3.52856e-32 4.50787e-17"/>
      <geometry>
        <mesh filename="package://assets/part_1__3.stl"/>
      </geometry>
      <material name="part_1_17_material">
        <color rgba="0.615686 0.811765 0.929412 1"/>
      </material>
    </visual>
    <collision>
      <origin xyz="0 3.1225e-17 0" rpy="3.14159 3.52856e-32 4.50787e-17"/>
      <geometry>
        <mesh filename="package://assets/part_1__3.stl"/>
      </geometry>
    </collision>
    <!-- Part part_2_9 -->
    <visual>
      <origin xyz="0 3.1225e-17 0" rpy="3.14159 3.52856e-32 4.50787e-17"/>
      <geometry>
        <mesh filename="package://assets/part_2__2.stl"/>
      </geometry>
      <material name="part_2_9_material">
        <color rgba="0.647059 0.647059 0.647059 1"/>
      </material>
    </visual>
    <collision>
      <origin xyz="0 3.1225e-17 0" rpy="3.14159 3.52856e-32 4.50787e-17"/>
      <geometry>
        <mesh filename="package://assets/part_2__2.stl"/>
      </geometry>
    </collision>
  </link>
  <!-- Joint from part1 to part_1_6 -->
  <joint name="wheel_2" type="continuous">
    <origin xyz="-0.191174 -0.129795 -0.0170868" rpy="2.45551e-16 -1.76174e-16 -0.898078"/>
    <parent link="part1"/>
    <child link="part_1_6"/>
    <axis xyz="0 0 1"/>
    <limit effort="10" velocity="10"/>
  </joint>
  <!-- Joint from part_9 to part1 -->
  <joint name="sub_l" type="revolute">
    <origin xyz="0.234047 -0.10062 -0.0199132" rpy="8.59465e-31 3.27328e-31 -7.81868e-16"/>
    <parent link="part_9"/>
    <child link="part1"/>
    <axis xyz="0 0 1"/>
    <limit effort="10" velocity="10" lower="-3.141592653589793" upper="3.141592653589793"/>
  </joint>
  <!-- Link part_1_7 -->
  <link name="part_1_7">
    <inertial>
      <origin xyz="0 0 0" rpy="0 0 0"/>
      <mass value="1e-09"/>
      <inertia ixx="1e-09" ixy="0" ixz="0" iyy="1e-09" iyz="0" izz="1e-09"/>
    </inertial>
    <!-- Part part_1_18 -->
    <visual>
      <origin xyz="2.77556e-17 0 0" rpy="3.14159 -1.24855e-32 1.58758e-17"/>
      <geometry>
        <mesh filename="package://assets/part_1__3.stl"/>
      </geometry>
      <material name="part_1_18_material">
        <color rgba="0.615686 0.811765 0.929412 1"/>
      </material>
    </visual>
    <collision>
      <origin xyz="2.77556e-17 0 0" rpy="3.14159 -1.24855e-32 1.58758e-17"/>
      <geometry>
        <mesh filename="package://assets/part_1__3.stl"/>
      </geometry>
    </collision>
    <!-- Part part_2_10 -->
    <visual>
      <origin xyz="2.77556e-17 0 0" rpy="3.14159 -1.24855e-32 1.58758e-17"/>
      <geometry>
        <mesh filename="package://assets/part_2__2.stl"/>
      </geometry>
      <material name="part_2_10_material">
        <color rgba="0.647059 0.647059 0.647059 1"/>
      </material>
    </visual>
    <collision>
      <origin xyz="2.77556e-17 0 0" rpy="3.14159 -1.24855e-32 1.58758e-17"/>
      <geometry>
        <mesh filename="package://assets/part_2__2.stl"/>
      </geometry>
    </collision>
  </link>
  <!-- Joint from part_9 to part_1_7 -->
  <joint name="wheel_1" type="continuous">
    <origin xyz="-0.298757 -0.245757 -0.02" rpy="-1.14868e-17 1.33339e-16 -0.816718"/>
    <parent link="part_9"/>
    <child link="part_1_7"/>
    <axis xyz="0 0 1"/>
    <limit effort="10" velocity="10"/>
  </joint>
  <!-- Joint from front_plate to part_9 -->
  <joint name="main_l" type="revolute">
    <origin xyz="0.239856 0.47631 -0.0801256" rpy="1.5708 -0.0664034 -1.11022e-16"/>
    <parent link="front_plate"/>
    <child link="part_9"/>
    <axis xyz="0 0 1"/>
    <limit effort="10" velocity="10" lower="-3.141592653589793" upper="3.141592653589793"/>
  </joint>
</robot>
